2022-09-08 10:16:03,241 — FileHandler — ERROR — file not found
Traceback (most recent call last):
  File "../src/file_handler.py", line 29, in read_csv
    df = pd.read_csv(csv_path)
  File "/home/sucess/anaconda3/lib/python3.7/site-packages/pandas/io/parsers.py", line 678, in parser_f
    return _read(filepath_or_buffer, kwds)
  File "/home/sucess/anaconda3/lib/python3.7/site-packages/pandas/io/parsers.py", line 440, in _read
    parser = TextFileReader(filepath_or_buffer, **kwds)
  File "/home/sucess/anaconda3/lib/python3.7/site-packages/pandas/io/parsers.py", line 787, in __init__
    self._make_engine(self.engine)
  File "/home/sucess/anaconda3/lib/python3.7/site-packages/pandas/io/parsers.py", line 1014, in _make_engine
    self._engine = CParserWrapper(self.f, **self.options)
  File "/home/sucess/anaconda3/lib/python3.7/site-packages/pandas/io/parsers.py", line 1708, in __init__
    self._reader = parsers.TextReader(src, **kwds)
  File "pandas/_libs/parsers.pyx", line 384, in pandas._libs.parsers.TextReader.__cinit__
  File "pandas/_libs/parsers.pyx", line 695, in pandas._libs.parsers.TextReader._setup_parser_source
FileNotFoundError: File b'train.csv' does not exist
2022-09-08 10:16:03,346 — FileHandler — ERROR — file not found
Traceback (most recent call last):
  File "../src/file_handler.py", line 29, in read_csv
    df = pd.read_csv(csv_path)
  File "/home/sucess/anaconda3/lib/python3.7/site-packages/pandas/io/parsers.py", line 678, in parser_f
    return _read(filepath_or_buffer, kwds)
  File "/home/sucess/anaconda3/lib/python3.7/site-packages/pandas/io/parsers.py", line 440, in _read
    parser = TextFileReader(filepath_or_buffer, **kwds)
  File "/home/sucess/anaconda3/lib/python3.7/site-packages/pandas/io/parsers.py", line 787, in __init__
    self._make_engine(self.engine)
  File "/home/sucess/anaconda3/lib/python3.7/site-packages/pandas/io/parsers.py", line 1014, in _make_engine
    self._engine = CParserWrapper(self.f, **self.options)
  File "/home/sucess/anaconda3/lib/python3.7/site-packages/pandas/io/parsers.py", line 1708, in __init__
    self._reader = parsers.TextReader(src, **kwds)
  File "pandas/_libs/parsers.pyx", line 384, in pandas._libs.parsers.TextReader.__cinit__
  File "pandas/_libs/parsers.pyx", line 695, in pandas._libs.parsers.TextReader._setup_parser_source
FileNotFoundError: File b'train.csv' does not exist
2022-09-08 10:17:04,085 — FileHandler — ERROR — file not found
Traceback (most recent call last):
  File "../src/file_handler.py", line 29, in read_csv
    df = pd.read_csv(csv_path)
  File "/home/sucess/anaconda3/lib/python3.7/site-packages/pandas/io/parsers.py", line 678, in parser_f
    return _read(filepath_or_buffer, kwds)
  File "/home/sucess/anaconda3/lib/python3.7/site-packages/pandas/io/parsers.py", line 440, in _read
    parser = TextFileReader(filepath_or_buffer, **kwds)
  File "/home/sucess/anaconda3/lib/python3.7/site-packages/pandas/io/parsers.py", line 787, in __init__
    self._make_engine(self.engine)
  File "/home/sucess/anaconda3/lib/python3.7/site-packages/pandas/io/parsers.py", line 1014, in _make_engine
    self._engine = CParserWrapper(self.f, **self.options)
  File "/home/sucess/anaconda3/lib/python3.7/site-packages/pandas/io/parsers.py", line 1708, in __init__
    self._reader = parsers.TextReader(src, **kwds)
  File "pandas/_libs/parsers.pyx", line 384, in pandas._libs.parsers.TextReader.__cinit__
  File "pandas/_libs/parsers.pyx", line 695, in pandas._libs.parsers.TextReader._setup_parser_source
FileNotFoundError: File b'..data/train.csv' does not exist
2022-09-08 10:17:04,091 — FileHandler — ERROR — file not found
Traceback (most recent call last):
  File "../src/file_handler.py", line 29, in read_csv
    df = pd.read_csv(csv_path)
  File "/home/sucess/anaconda3/lib/python3.7/site-packages/pandas/io/parsers.py", line 678, in parser_f
    return _read(filepath_or_buffer, kwds)
  File "/home/sucess/anaconda3/lib/python3.7/site-packages/pandas/io/parsers.py", line 440, in _read
    parser = TextFileReader(filepath_or_buffer, **kwds)
  File "/home/sucess/anaconda3/lib/python3.7/site-packages/pandas/io/parsers.py", line 787, in __init__
    self._make_engine(self.engine)
  File "/home/sucess/anaconda3/lib/python3.7/site-packages/pandas/io/parsers.py", line 1014, in _make_engine
    self._engine = CParserWrapper(self.f, **self.options)
  File "/home/sucess/anaconda3/lib/python3.7/site-packages/pandas/io/parsers.py", line 1708, in __init__
    self._reader = parsers.TextReader(src, **kwds)
  File "pandas/_libs/parsers.pyx", line 384, in pandas._libs.parsers.TextReader.__cinit__
  File "pandas/_libs/parsers.pyx", line 695, in pandas._libs.parsers.TextReader._setup_parser_source
FileNotFoundError: File b',,/data/test.csv' does not exist
2022-09-08 10:17:22,318 — FileHandler — ERROR — file not found
Traceback (most recent call last):
  File "../src/file_handler.py", line 29, in read_csv
    df = pd.read_csv(csv_path)
  File "/home/sucess/anaconda3/lib/python3.7/site-packages/pandas/io/parsers.py", line 678, in parser_f
    return _read(filepath_or_buffer, kwds)
  File "/home/sucess/anaconda3/lib/python3.7/site-packages/pandas/io/parsers.py", line 440, in _read
    parser = TextFileReader(filepath_or_buffer, **kwds)
  File "/home/sucess/anaconda3/lib/python3.7/site-packages/pandas/io/parsers.py", line 787, in __init__
    self._make_engine(self.engine)
  File "/home/sucess/anaconda3/lib/python3.7/site-packages/pandas/io/parsers.py", line 1014, in _make_engine
    self._engine = CParserWrapper(self.f, **self.options)
  File "/home/sucess/anaconda3/lib/python3.7/site-packages/pandas/io/parsers.py", line 1708, in __init__
    self._reader = parsers.TextReader(src, **kwds)
  File "pandas/_libs/parsers.pyx", line 384, in pandas._libs.parsers.TextReader.__cinit__
  File "pandas/_libs/parsers.pyx", line 695, in pandas._libs.parsers.TextReader._setup_parser_source
FileNotFoundError: File b'..data/train.csv' does not exist
2022-09-08 10:17:22,768 — FileHandler — DEBUG — file read as csv
2022-09-08 10:17:43,679 — FileHandler — DEBUG — file read as csv
2022-09-08 10:17:43,726 — FileHandler — DEBUG — file read as csv
2022-09-08 10:22:15,115 — FileHandler — DEBUG — file read as csv
2022-09-08 10:22:15,174 — FileHandler — DEBUG — file read as csv
2022-09-08 10:22:44,581 — FileHandler — ERROR — file not found
Traceback (most recent call last):
  File "../src/file_handler.py", line 29, in read_csv
    df = pd.read_csv(csv_path)
  File "/home/sucess/anaconda3/lib/python3.7/site-packages/pandas/io/parsers.py", line 678, in parser_f
    return _read(filepath_or_buffer, kwds)
  File "/home/sucess/anaconda3/lib/python3.7/site-packages/pandas/io/parsers.py", line 440, in _read
    parser = TextFileReader(filepath_or_buffer, **kwds)
  File "/home/sucess/anaconda3/lib/python3.7/site-packages/pandas/io/parsers.py", line 787, in __init__
    self._make_engine(self.engine)
  File "/home/sucess/anaconda3/lib/python3.7/site-packages/pandas/io/parsers.py", line 1014, in _make_engine
    self._engine = CParserWrapper(self.f, **self.options)
  File "/home/sucess/anaconda3/lib/python3.7/site-packages/pandas/io/parsers.py", line 1708, in __init__
    self._reader = parsers.TextReader(src, **kwds)
  File "pandas/_libs/parsers.pyx", line 384, in pandas._libs.parsers.TextReader.__cinit__
  File "pandas/_libs/parsers.pyx", line 695, in pandas._libs.parsers.TextReader._setup_parser_source
FileNotFoundError: File b'../data/train.csv' does not exist
2022-09-08 10:22:44,643 — FileHandler — DEBUG — file read as csv
2022-09-08 10:23:28,585 — FileHandler — ERROR — file not found
Traceback (most recent call last):
  File "../src/file_handler.py", line 29, in read_csv
    df = pd.read_csv(csv_path)
  File "/home/sucess/anaconda3/lib/python3.7/site-packages/pandas/io/parsers.py", line 678, in parser_f
    return _read(filepath_or_buffer, kwds)
  File "/home/sucess/anaconda3/lib/python3.7/site-packages/pandas/io/parsers.py", line 440, in _read
    parser = TextFileReader(filepath_or_buffer, **kwds)
  File "/home/sucess/anaconda3/lib/python3.7/site-packages/pandas/io/parsers.py", line 787, in __init__
    self._make_engine(self.engine)
  File "/home/sucess/anaconda3/lib/python3.7/site-packages/pandas/io/parsers.py", line 1014, in _make_engine
    self._engine = CParserWrapper(self.f, **self.options)
  File "/home/sucess/anaconda3/lib/python3.7/site-packages/pandas/io/parsers.py", line 1708, in __init__
    self._reader = parsers.TextReader(src, **kwds)
  File "pandas/_libs/parsers.pyx", line 384, in pandas._libs.parsers.TextReader.__cinit__
  File "pandas/_libs/parsers.pyx", line 695, in pandas._libs.parsers.TextReader._setup_parser_source
FileNotFoundError: File b'../data/train.csv' does not exist
2022-09-08 10:23:28,589 — FileHandler — ERROR — file not found
Traceback (most recent call last):
  File "../src/file_handler.py", line 29, in read_csv
    df = pd.read_csv(csv_path)
  File "/home/sucess/anaconda3/lib/python3.7/site-packages/pandas/io/parsers.py", line 678, in parser_f
    return _read(filepath_or_buffer, kwds)
  File "/home/sucess/anaconda3/lib/python3.7/site-packages/pandas/io/parsers.py", line 440, in _read
    parser = TextFileReader(filepath_or_buffer, **kwds)
  File "/home/sucess/anaconda3/lib/python3.7/site-packages/pandas/io/parsers.py", line 787, in __init__
    self._make_engine(self.engine)
  File "/home/sucess/anaconda3/lib/python3.7/site-packages/pandas/io/parsers.py", line 1014, in _make_engine
    self._engine = CParserWrapper(self.f, **self.options)
  File "/home/sucess/anaconda3/lib/python3.7/site-packages/pandas/io/parsers.py", line 1708, in __init__
    self._reader = parsers.TextReader(src, **kwds)
  File "pandas/_libs/parsers.pyx", line 384, in pandas._libs.parsers.TextReader.__cinit__
  File "pandas/_libs/parsers.pyx", line 695, in pandas._libs.parsers.TextReader._setup_parser_source
FileNotFoundError: File b'../data/test.csv' does not exist
2022-09-08 10:33:27,500 — FileHandler — ERROR — file not found
Traceback (most recent call last):
  File "../src/file_handler.py", line 29, in read_csv
    try:
  File "/home/sucess/anaconda3/lib/python3.7/site-packages/pandas/io/parsers.py", line 678, in parser_f
    return _read(filepath_or_buffer, kwds)
  File "/home/sucess/anaconda3/lib/python3.7/site-packages/pandas/io/parsers.py", line 440, in _read
    parser = TextFileReader(filepath_or_buffer, **kwds)
  File "/home/sucess/anaconda3/lib/python3.7/site-packages/pandas/io/parsers.py", line 787, in __init__
    self._make_engine(self.engine)
  File "/home/sucess/anaconda3/lib/python3.7/site-packages/pandas/io/parsers.py", line 1014, in _make_engine
    self._engine = CParserWrapper(self.f, **self.options)
  File "/home/sucess/anaconda3/lib/python3.7/site-packages/pandas/io/parsers.py", line 1708, in __init__
    self._reader = parsers.TextReader(src, **kwds)
  File "pandas/_libs/parsers.pyx", line 384, in pandas._libs.parsers.TextReader.__cinit__
  File "pandas/_libs/parsers.pyx", line 695, in pandas._libs.parsers.TextReader._setup_parser_source
FileNotFoundError: File b'../data/train.csv' does not exist
2022-09-08 10:33:27,506 — FileHandler — ERROR — file not found
Traceback (most recent call last):
  File "../src/file_handler.py", line 29, in read_csv
    try:
  File "/home/sucess/anaconda3/lib/python3.7/site-packages/pandas/io/parsers.py", line 678, in parser_f
    return _read(filepath_or_buffer, kwds)
  File "/home/sucess/anaconda3/lib/python3.7/site-packages/pandas/io/parsers.py", line 440, in _read
    parser = TextFileReader(filepath_or_buffer, **kwds)
  File "/home/sucess/anaconda3/lib/python3.7/site-packages/pandas/io/parsers.py", line 787, in __init__
    self._make_engine(self.engine)
  File "/home/sucess/anaconda3/lib/python3.7/site-packages/pandas/io/parsers.py", line 1014, in _make_engine
    self._engine = CParserWrapper(self.f, **self.options)
  File "/home/sucess/anaconda3/lib/python3.7/site-packages/pandas/io/parsers.py", line 1708, in __init__
    self._reader = parsers.TextReader(src, **kwds)
  File "pandas/_libs/parsers.pyx", line 384, in pandas._libs.parsers.TextReader.__cinit__
  File "pandas/_libs/parsers.pyx", line 695, in pandas._libs.parsers.TextReader._setup_parser_source
FileNotFoundError: File b'../data/test.csv' does not exist
2022-09-08 10:43:28,768 — FileHandler — ERROR — DVC data getter raised an exception
Traceback (most recent call last):
  File "../src/file_handler.py", line 53, in dvc_get_data
    content = dvc.api.read(path=path,
NameError: name 'dvc' is not defined
2022-09-08 10:44:31,424 — FileHandler — ERROR — DVC data getter raised an exception
Traceback (most recent call last):
  File "../src/file_handler.py", line 53, in dvc_get_data
    def dvc_get_data(path: str, version: str, repo: str = '../'):
NameError: name 'dvc' is not defined
2022-09-08 10:44:43,007 — FileHandler — ERROR — DVC data getter raised an exception
Traceback (most recent call last):
  File "../src/file_handler.py", line 53, in dvc_get_data
    def dvc_get_data(path: str, version: str, repo: str = '../'):
NameError: name 'dvc' is not defined
2022-09-08 10:47:52,643 — FileHandler — INFO — DVC: CSV file read with path: data/train.csv | version: v3 | from: ../
2022-09-08 10:49:25,392 — FileHandler — INFO — DVC: CSV file read with path: data/train.csv | version: v3 | from: ../
2022-09-08 10:49:25,864 — FileHandler — ERROR — DVC data getter raised an exception
Traceback (most recent call last):
  File "/home/sucess/anaconda3/lib/python3.7/site-packages/dvc/scm.py", line 140, in resolve_rev
    return scm.resolve_rev(fix_exp_head(scm, rev))
  File "/home/sucess/anaconda3/lib/python3.7/site-packages/scmrepo/git/__init__.py", line 289, in _backend_func
    result = func(*args, **kwargs)
  File "/home/sucess/anaconda3/lib/python3.7/site-packages/scmrepo/git/backend/pygit2.py", line 297, in resolve_rev
    raise RevError(f"unknown Git revision '{rev}'")
scmrepo.exceptions.RevError: unknown Git revision 'v4'

During handling of the above exception, another exception occurred:

Traceback (most recent call last):
  File "../src/file_handler.py", line 57, in dvc_get_data
    rev=version)
  File "/home/sucess/anaconda3/lib/python3.7/site-packages/dvc/api.py", line 89, in read
    path, repo=repo, rev=rev, remote=remote, mode=mode, encoding=encoding
  File "/home/sucess/anaconda3/lib/python3.7/contextlib.py", line 112, in __enter__
    return next(self.gen)
  File "/home/sucess/anaconda3/lib/python3.7/site-packages/dvc/api.py", line 75, in _open
    with Repo.open(repo, rev=rev, subrepos=True, uninitialized=True) as _repo:
  File "/home/sucess/anaconda3/lib/python3.7/site-packages/dvc/repo/__init__.py", line 233, in open
    return Repo(url, *args, **kwargs)
  File "/home/sucess/anaconda3/lib/python3.7/site-packages/dvc/repo/__init__.py", line 176, in __init__
    root_dir=root_dir, fs=self.fs, uninitialized=uninitialized
  File "/home/sucess/anaconda3/lib/python3.7/site-packages/dvc/repo/__init__.py", line 95, in _get_repo_dirs
    root_dir = self.find_root(root_dir, fs)
  File "/home/sucess/anaconda3/lib/python3.7/site-packages/dvc/repo/__init__.py", line 319, in find_root
    if not fs.isdir(root_dir):
  File "/home/sucess/anaconda3/lib/python3.7/site-packages/dvc/fs/base.py", line 168, in isdir
    return self.fs.isdir(path)
  File "/home/sucess/anaconda3/lib/python3.7/site-packages/funcy/objects.py", line 50, in __get__
    return prop.__get__(instance, type)
  File "/home/sucess/anaconda3/lib/python3.7/site-packages/funcy/objects.py", line 28, in __get__
    res = instance.__dict__[self.fget.__name__] = self.fget(instance)
  File "/home/sucess/anaconda3/lib/python3.7/site-packages/dvc/fs/git.py", line 48, in fs
    return FsspecGitFileSystem(**self.fs_args)
  File "/home/sucess/anaconda3/lib/python3.7/site-packages/fsspec/spec.py", line 76, in __call__
    obj = super().__call__(*args, **kwargs)
  File "/home/sucess/anaconda3/lib/python3.7/site-packages/scmrepo/fs.py", line 54, in __init__
    resolved = resolver(scm, rev or "HEAD")
  File "/home/sucess/anaconda3/lib/python3.7/site-packages/dvc/scm.py", line 157, in resolve_rev
    raise RevError(str(exc))
dvc.scm.RevError: unknown Git revision 'v4'
2022-09-08 10:49:57,411 — FileHandler — INFO — DVC: CSV file read with path: data/train.csv | version: v3 | from: ../
2022-09-08 10:49:57,475 — FileHandler — ERROR — DVC data getter raised an exception
Traceback (most recent call last):
  File "/home/sucess/anaconda3/lib/python3.7/site-packages/dvc/fs/dvc.py", line 114, in info
    outs = list(self.repo.index.tree.iteritems(key))
  File "/home/sucess/anaconda3/lib/python3.7/site-packages/dvc/data/tree.py", line 92, in iteritems
    for key, (meta, hash_info) in self._trie.iteritems(**kwargs):
  File "/home/sucess/anaconda3/lib/python3.7/site-packages/pygtrie.py", line 718, in iteritems
    node, _ = self._get_node(prefix)
  File "/home/sucess/anaconda3/lib/python3.7/site-packages/pygtrie.py", line 630, in _get_node
    raise KeyError(key)
KeyError: ('repo', '..', 'data', 'test.csv')

The above exception was the direct cause of the following exception:

Traceback (most recent call last):
  File "/home/sucess/anaconda3/lib/python3.7/site-packages/dvc/repo/__init__.py", line 499, in open_by_relpath
    path, mode=mode, encoding=encoding, remote=remote
  File "/home/sucess/anaconda3/lib/python3.7/site-packages/dvc/fs/base.py", line 186, in open
    return self.fs.open(path, mode=mode, encoding=encoding, **kwargs)
  File "/home/sucess/anaconda3/lib/python3.7/site-packages/dvc/fs/repo.py", line 309, in open
    return dvc_fs.open(dvc_path, mode=mode, encoding=encoding, **kwargs)
  File "/home/sucess/anaconda3/lib/python3.7/site-packages/dvc/fs/base.py", line 186, in open
    return self.fs.open(path, mode=mode, encoding=encoding, **kwargs)
  File "/home/sucess/anaconda3/lib/python3.7/site-packages/dvc/fs/dvc.py", line 77, in open
    fs, fspath = self._get_fs_path(path, **kwargs)
  File "/home/sucess/anaconda3/lib/python3.7/site-packages/dvc/fs/dvc.py", line 54, in _get_fs_path
    info = self.info(path)
  File "/home/sucess/anaconda3/lib/python3.7/site-packages/dvc/fs/dvc.py", line 116, in info
    raise FileNotFoundError from exc
FileNotFoundError

The above exception was the direct cause of the following exception:

Traceback (most recent call last):
  File "../src/file_handler.py", line 57, in dvc_get_data
    rev=version)
  File "/home/sucess/anaconda3/lib/python3.7/site-packages/dvc/api.py", line 89, in read
    path, repo=repo, rev=rev, remote=remote, mode=mode, encoding=encoding
  File "/home/sucess/anaconda3/lib/python3.7/contextlib.py", line 112, in __enter__
    return next(self.gen)
  File "/home/sucess/anaconda3/lib/python3.7/site-packages/dvc/api.py", line 77, in _open
    path, remote=remote, mode=mode, encoding=encoding
  File "/home/sucess/anaconda3/lib/python3.7/contextlib.py", line 112, in __enter__
    return next(self.gen)
  File "/home/sucess/anaconda3/lib/python3.7/site-packages/dvc/repo/__init__.py", line 503, in open_by_relpath
    raise FileMissingError(path) from exc
dvc.exceptions.FileMissingError: Can't find '../data/test.csv' neither locally nor on remote
2022-09-08 10:50:25,231 — FileHandler — INFO — DVC: CSV file read with path: data/train.csv | version: v3 | from: ../
2022-09-08 10:50:25,325 — FileHandler — ERROR — DVC data getter raised an exception
Traceback (most recent call last):
  File "/home/sucess/anaconda3/lib/python3.7/site-packages/dvc/fs/dvc.py", line 114, in info
    outs = list(self.repo.index.tree.iteritems(key))
  File "/home/sucess/anaconda3/lib/python3.7/site-packages/dvc/data/tree.py", line 92, in iteritems
    for key, (meta, hash_info) in self._trie.iteritems(**kwargs):
  File "/home/sucess/anaconda3/lib/python3.7/site-packages/pygtrie.py", line 718, in iteritems
    node, _ = self._get_node(prefix)
  File "/home/sucess/anaconda3/lib/python3.7/site-packages/pygtrie.py", line 630, in _get_node
    raise KeyError(key)
KeyError: ('repo', '..', 'data', 'test.csv')

The above exception was the direct cause of the following exception:

Traceback (most recent call last):
  File "/home/sucess/anaconda3/lib/python3.7/site-packages/dvc/repo/__init__.py", line 499, in open_by_relpath
    path, mode=mode, encoding=encoding, remote=remote
  File "/home/sucess/anaconda3/lib/python3.7/site-packages/dvc/fs/base.py", line 186, in open
    return self.fs.open(path, mode=mode, encoding=encoding, **kwargs)
  File "/home/sucess/anaconda3/lib/python3.7/site-packages/dvc/fs/repo.py", line 309, in open
    return dvc_fs.open(dvc_path, mode=mode, encoding=encoding, **kwargs)
  File "/home/sucess/anaconda3/lib/python3.7/site-packages/dvc/fs/base.py", line 186, in open
    return self.fs.open(path, mode=mode, encoding=encoding, **kwargs)
  File "/home/sucess/anaconda3/lib/python3.7/site-packages/dvc/fs/dvc.py", line 77, in open
    fs, fspath = self._get_fs_path(path, **kwargs)
  File "/home/sucess/anaconda3/lib/python3.7/site-packages/dvc/fs/dvc.py", line 54, in _get_fs_path
    info = self.info(path)
  File "/home/sucess/anaconda3/lib/python3.7/site-packages/dvc/fs/dvc.py", line 116, in info
    raise FileNotFoundError from exc
FileNotFoundError

The above exception was the direct cause of the following exception:

Traceback (most recent call last):
  File "../src/file_handler.py", line 57, in dvc_get_data
    rev=version)
  File "/home/sucess/anaconda3/lib/python3.7/site-packages/dvc/api.py", line 89, in read
    path, repo=repo, rev=rev, remote=remote, mode=mode, encoding=encoding
  File "/home/sucess/anaconda3/lib/python3.7/contextlib.py", line 112, in __enter__
    return next(self.gen)
  File "/home/sucess/anaconda3/lib/python3.7/site-packages/dvc/api.py", line 77, in _open
    path, remote=remote, mode=mode, encoding=encoding
  File "/home/sucess/anaconda3/lib/python3.7/contextlib.py", line 112, in __enter__
    return next(self.gen)
  File "/home/sucess/anaconda3/lib/python3.7/site-packages/dvc/repo/__init__.py", line 503, in open_by_relpath
    raise FileMissingError(path) from exc
dvc.exceptions.FileMissingError: Can't find '../data/test.csv' neither locally nor on remote
2022-09-08 10:50:42,486 — FileHandler — INFO — DVC: CSV file read with path: data/train.csv | version: v3 | from: ../
2022-09-08 10:50:42,506 — FileHandler — ERROR — DVC data getter raised an exception
Traceback (most recent call last):
  File "/home/sucess/anaconda3/lib/python3.7/site-packages/dvc/scm.py", line 140, in resolve_rev
    return scm.resolve_rev(fix_exp_head(scm, rev))
  File "/home/sucess/anaconda3/lib/python3.7/site-packages/scmrepo/git/__init__.py", line 289, in _backend_func
    result = func(*args, **kwargs)
  File "/home/sucess/anaconda3/lib/python3.7/site-packages/scmrepo/git/backend/pygit2.py", line 297, in resolve_rev
    raise RevError(f"unknown Git revision '{rev}'")
scmrepo.exceptions.RevError: unknown Git revision 'vt1'

During handling of the above exception, another exception occurred:

Traceback (most recent call last):
  File "../src/file_handler.py", line 57, in dvc_get_data
    rev=version)
  File "/home/sucess/anaconda3/lib/python3.7/site-packages/dvc/api.py", line 89, in read
    path, repo=repo, rev=rev, remote=remote, mode=mode, encoding=encoding
  File "/home/sucess/anaconda3/lib/python3.7/contextlib.py", line 112, in __enter__
    return next(self.gen)
  File "/home/sucess/anaconda3/lib/python3.7/site-packages/dvc/api.py", line 75, in _open
    with Repo.open(repo, rev=rev, subrepos=True, uninitialized=True) as _repo:
  File "/home/sucess/anaconda3/lib/python3.7/site-packages/dvc/repo/__init__.py", line 233, in open
    return Repo(url, *args, **kwargs)
  File "/home/sucess/anaconda3/lib/python3.7/site-packages/dvc/repo/__init__.py", line 176, in __init__
    root_dir=root_dir, fs=self.fs, uninitialized=uninitialized
  File "/home/sucess/anaconda3/lib/python3.7/site-packages/dvc/repo/__init__.py", line 95, in _get_repo_dirs
    root_dir = self.find_root(root_dir, fs)
  File "/home/sucess/anaconda3/lib/python3.7/site-packages/dvc/repo/__init__.py", line 319, in find_root
    if not fs.isdir(root_dir):
  File "/home/sucess/anaconda3/lib/python3.7/site-packages/dvc/fs/base.py", line 168, in isdir
    return self.fs.isdir(path)
  File "/home/sucess/anaconda3/lib/python3.7/site-packages/funcy/objects.py", line 50, in __get__
    return prop.__get__(instance, type)
  File "/home/sucess/anaconda3/lib/python3.7/site-packages/funcy/objects.py", line 28, in __get__
    res = instance.__dict__[self.fget.__name__] = self.fget(instance)
  File "/home/sucess/anaconda3/lib/python3.7/site-packages/dvc/fs/git.py", line 48, in fs
    return FsspecGitFileSystem(**self.fs_args)
  File "/home/sucess/anaconda3/lib/python3.7/site-packages/fsspec/spec.py", line 76, in __call__
    obj = super().__call__(*args, **kwargs)
  File "/home/sucess/anaconda3/lib/python3.7/site-packages/scmrepo/fs.py", line 54, in __init__
    resolved = resolver(scm, rev or "HEAD")
  File "/home/sucess/anaconda3/lib/python3.7/site-packages/dvc/scm.py", line 157, in resolve_rev
    raise RevError(str(exc))
dvc.scm.RevError: unknown Git revision 'vt1'
2022-09-08 10:51:13,473 — FileHandler — INFO — DVC: CSV file read with path: data/train.csv | version: v3 | from: ../
2022-09-08 10:51:13,517 — FileHandler — ERROR — DVC data getter raised an exception
Traceback (most recent call last):
  File "/home/sucess/anaconda3/lib/python3.7/site-packages/dvc/fs/dvc.py", line 114, in info
    outs = list(self.repo.index.tree.iteritems(key))
  File "/home/sucess/anaconda3/lib/python3.7/site-packages/dvc/data/tree.py", line 92, in iteritems
    for key, (meta, hash_info) in self._trie.iteritems(**kwargs):
  File "/home/sucess/anaconda3/lib/python3.7/site-packages/pygtrie.py", line 718, in iteritems
    node, _ = self._get_node(prefix)
  File "/home/sucess/anaconda3/lib/python3.7/site-packages/pygtrie.py", line 630, in _get_node
    raise KeyError(key)
KeyError: ('repo', '..', 'data', 'test.csv')

The above exception was the direct cause of the following exception:

Traceback (most recent call last):
  File "/home/sucess/anaconda3/lib/python3.7/site-packages/dvc/repo/__init__.py", line 499, in open_by_relpath
    path, mode=mode, encoding=encoding, remote=remote
  File "/home/sucess/anaconda3/lib/python3.7/site-packages/dvc/fs/base.py", line 186, in open
    return self.fs.open(path, mode=mode, encoding=encoding, **kwargs)
  File "/home/sucess/anaconda3/lib/python3.7/site-packages/dvc/fs/repo.py", line 309, in open
    return dvc_fs.open(dvc_path, mode=mode, encoding=encoding, **kwargs)
  File "/home/sucess/anaconda3/lib/python3.7/site-packages/dvc/fs/base.py", line 186, in open
    return self.fs.open(path, mode=mode, encoding=encoding, **kwargs)
  File "/home/sucess/anaconda3/lib/python3.7/site-packages/dvc/fs/dvc.py", line 77, in open
    fs, fspath = self._get_fs_path(path, **kwargs)
  File "/home/sucess/anaconda3/lib/python3.7/site-packages/dvc/fs/dvc.py", line 54, in _get_fs_path
    info = self.info(path)
  File "/home/sucess/anaconda3/lib/python3.7/site-packages/dvc/fs/dvc.py", line 116, in info
    raise FileNotFoundError from exc
FileNotFoundError

The above exception was the direct cause of the following exception:

Traceback (most recent call last):
  File "../src/file_handler.py", line 57, in dvc_get_data
    rev=version)
  File "/home/sucess/anaconda3/lib/python3.7/site-packages/dvc/api.py", line 89, in read
    path, repo=repo, rev=rev, remote=remote, mode=mode, encoding=encoding
  File "/home/sucess/anaconda3/lib/python3.7/contextlib.py", line 112, in __enter__
    return next(self.gen)
  File "/home/sucess/anaconda3/lib/python3.7/site-packages/dvc/api.py", line 77, in _open
    path, remote=remote, mode=mode, encoding=encoding
  File "/home/sucess/anaconda3/lib/python3.7/contextlib.py", line 112, in __enter__
    return next(self.gen)
  File "/home/sucess/anaconda3/lib/python3.7/site-packages/dvc/repo/__init__.py", line 503, in open_by_relpath
    raise FileMissingError(path) from exc
dvc.exceptions.FileMissingError: Can't find '../data/test.csv' neither locally nor on remote
2022-09-08 10:51:27,892 — FileHandler — INFO — DVC: CSV file read with path: data/train.csv | version: v3 | from: ../
2022-09-08 10:51:27,924 — FileHandler — ERROR — DVC data getter raised an exception
Traceback (most recent call last):
  File "/home/sucess/anaconda3/lib/python3.7/site-packages/dvc/fs/dvc.py", line 114, in info
    outs = list(self.repo.index.tree.iteritems(key))
  File "/home/sucess/anaconda3/lib/python3.7/site-packages/dvc/data/tree.py", line 92, in iteritems
    for key, (meta, hash_info) in self._trie.iteritems(**kwargs):
  File "/home/sucess/anaconda3/lib/python3.7/site-packages/pygtrie.py", line 718, in iteritems
    node, _ = self._get_node(prefix)
  File "/home/sucess/anaconda3/lib/python3.7/site-packages/pygtrie.py", line 630, in _get_node
    raise KeyError(key)
KeyError: ('repo', '..', 'data', 'test.csv')

The above exception was the direct cause of the following exception:

Traceback (most recent call last):
  File "/home/sucess/anaconda3/lib/python3.7/site-packages/dvc/repo/__init__.py", line 499, in open_by_relpath
    path, mode=mode, encoding=encoding, remote=remote
  File "/home/sucess/anaconda3/lib/python3.7/site-packages/dvc/fs/base.py", line 186, in open
    return self.fs.open(path, mode=mode, encoding=encoding, **kwargs)
  File "/home/sucess/anaconda3/lib/python3.7/site-packages/dvc/fs/repo.py", line 309, in open
    return dvc_fs.open(dvc_path, mode=mode, encoding=encoding, **kwargs)
  File "/home/sucess/anaconda3/lib/python3.7/site-packages/dvc/fs/base.py", line 186, in open
    return self.fs.open(path, mode=mode, encoding=encoding, **kwargs)
  File "/home/sucess/anaconda3/lib/python3.7/site-packages/dvc/fs/dvc.py", line 77, in open
    fs, fspath = self._get_fs_path(path, **kwargs)
  File "/home/sucess/anaconda3/lib/python3.7/site-packages/dvc/fs/dvc.py", line 54, in _get_fs_path
    info = self.info(path)
  File "/home/sucess/anaconda3/lib/python3.7/site-packages/dvc/fs/dvc.py", line 116, in info
    raise FileNotFoundError from exc
FileNotFoundError

The above exception was the direct cause of the following exception:

Traceback (most recent call last):
  File "../src/file_handler.py", line 57, in dvc_get_data
    rev=version)
  File "/home/sucess/anaconda3/lib/python3.7/site-packages/dvc/api.py", line 89, in read
    path, repo=repo, rev=rev, remote=remote, mode=mode, encoding=encoding
  File "/home/sucess/anaconda3/lib/python3.7/contextlib.py", line 112, in __enter__
    return next(self.gen)
  File "/home/sucess/anaconda3/lib/python3.7/site-packages/dvc/api.py", line 77, in _open
    path, remote=remote, mode=mode, encoding=encoding
  File "/home/sucess/anaconda3/lib/python3.7/contextlib.py", line 112, in __enter__
    return next(self.gen)
  File "/home/sucess/anaconda3/lib/python3.7/site-packages/dvc/repo/__init__.py", line 503, in open_by_relpath
    raise FileMissingError(path) from exc
dvc.exceptions.FileMissingError: Can't find '../data/test.csv' neither locally nor on remote
2022-09-08 10:51:45,250 — FileHandler — INFO — DVC: CSV file read with path: data/train.csv | version: v3 | from: ../
2022-09-08 10:51:45,290 — FileHandler — ERROR — DVC data getter raised an exception
Traceback (most recent call last):
  File "/home/sucess/anaconda3/lib/python3.7/site-packages/dvc/fs/dvc.py", line 114, in info
    outs = list(self.repo.index.tree.iteritems(key))
  File "/home/sucess/anaconda3/lib/python3.7/site-packages/dvc/data/tree.py", line 92, in iteritems
    for key, (meta, hash_info) in self._trie.iteritems(**kwargs):
  File "/home/sucess/anaconda3/lib/python3.7/site-packages/pygtrie.py", line 718, in iteritems
    node, _ = self._get_node(prefix)
  File "/home/sucess/anaconda3/lib/python3.7/site-packages/pygtrie.py", line 630, in _get_node
    raise KeyError(key)
KeyError: ('repo', '..', 'data', 'test.csv')

The above exception was the direct cause of the following exception:

Traceback (most recent call last):
  File "/home/sucess/anaconda3/lib/python3.7/site-packages/dvc/repo/__init__.py", line 499, in open_by_relpath
    path, mode=mode, encoding=encoding, remote=remote
  File "/home/sucess/anaconda3/lib/python3.7/site-packages/dvc/fs/base.py", line 186, in open
    return self.fs.open(path, mode=mode, encoding=encoding, **kwargs)
  File "/home/sucess/anaconda3/lib/python3.7/site-packages/dvc/fs/repo.py", line 309, in open
    return dvc_fs.open(dvc_path, mode=mode, encoding=encoding, **kwargs)
  File "/home/sucess/anaconda3/lib/python3.7/site-packages/dvc/fs/base.py", line 186, in open
    return self.fs.open(path, mode=mode, encoding=encoding, **kwargs)
  File "/home/sucess/anaconda3/lib/python3.7/site-packages/dvc/fs/dvc.py", line 77, in open
    fs, fspath = self._get_fs_path(path, **kwargs)
  File "/home/sucess/anaconda3/lib/python3.7/site-packages/dvc/fs/dvc.py", line 54, in _get_fs_path
    info = self.info(path)
  File "/home/sucess/anaconda3/lib/python3.7/site-packages/dvc/fs/dvc.py", line 116, in info
    raise FileNotFoundError from exc
FileNotFoundError

The above exception was the direct cause of the following exception:

Traceback (most recent call last):
  File "../src/file_handler.py", line 57, in dvc_get_data
    rev=version)
  File "/home/sucess/anaconda3/lib/python3.7/site-packages/dvc/api.py", line 89, in read
    path, repo=repo, rev=rev, remote=remote, mode=mode, encoding=encoding
  File "/home/sucess/anaconda3/lib/python3.7/contextlib.py", line 112, in __enter__
    return next(self.gen)
  File "/home/sucess/anaconda3/lib/python3.7/site-packages/dvc/api.py", line 77, in _open
    path, remote=remote, mode=mode, encoding=encoding
  File "/home/sucess/anaconda3/lib/python3.7/contextlib.py", line 112, in __enter__
    return next(self.gen)
  File "/home/sucess/anaconda3/lib/python3.7/site-packages/dvc/repo/__init__.py", line 503, in open_by_relpath
    raise FileMissingError(path) from exc
dvc.exceptions.FileMissingError: Can't find '../data/test.csv' neither locally nor on remote
2022-09-08 10:52:35,243 — FileHandler — ERROR — DVC data getter raised an exception
Traceback (most recent call last):
  File "/home/sucess/anaconda3/lib/python3.7/site-packages/scmrepo/git/backend/dulwich/__init__.py", line 193, in clone
    repo = clone_from()
  File "/home/sucess/anaconda3/lib/python3.7/site-packages/dulwich/porcelain.py", line 547, in clone
    depth=depth,
  File "/home/sucess/anaconda3/lib/python3.7/site-packages/dulwich/client.py", line 760, in clone
    result = self.fetch(path, target, progress=progress, depth=depth)
  File "/home/sucess/anaconda3/lib/python3.7/site-packages/dulwich/client.py", line 1501, in fetch
    with self._open_repo(path) as r:
  File "/home/sucess/anaconda3/lib/python3.7/site-packages/dulwich/client.py", line 1423, in _open_repo
    return closing(Repo(path))
  File "/home/sucess/anaconda3/lib/python3.7/site-packages/dulwich/repo.py", line 1091, in __init__
    "No git repository was found at %(path)s" % dict(path=root)
dulwich.errors.NotGitRepository: No git repository was found at Pharmaceutical_sales_prediction

The above exception was the direct cause of the following exception:

Traceback (most recent call last):
  File "/home/sucess/anaconda3/lib/python3.7/site-packages/dvc/scm.py", line 126, in clone
    git = Git.clone(url, to_path, progress=pbar.update_git, **kwargs)
  File "/home/sucess/anaconda3/lib/python3.7/site-packages/scmrepo/git/__init__.py", line 143, in clone
    backend.clone(url, to_path, **kwargs)
  File "/home/sucess/anaconda3/lib/python3.7/site-packages/scmrepo/git/backend/dulwich/__init__.py", line 196, in clone
    raise CloneError(url, to_path) from exc
scmrepo.exceptions.CloneError: Failed to clone repo 'Pharmaceutical_sales_prediction' to '/tmp/tmp0ui4smvtdvc-clone'

During handling of the above exception, another exception occurred:

Traceback (most recent call last):
  File "../src/file_handler.py", line 57, in dvc_get_data
    rev=version)
  File "/home/sucess/anaconda3/lib/python3.7/site-packages/dvc/api.py", line 89, in read
    path, repo=repo, rev=rev, remote=remote, mode=mode, encoding=encoding
  File "/home/sucess/anaconda3/lib/python3.7/contextlib.py", line 112, in __enter__
    return next(self.gen)
  File "/home/sucess/anaconda3/lib/python3.7/site-packages/dvc/api.py", line 75, in _open
    with Repo.open(repo, rev=rev, subrepos=True, uninitialized=True) as _repo:
  File "/home/sucess/anaconda3/lib/python3.7/contextlib.py", line 112, in __enter__
    return next(self.gen)
  File "/home/sucess/anaconda3/lib/python3.7/site-packages/dvc/external_repo.py", line 39, in external_repo
    path = _cached_clone(url, rev, for_write=for_write)
  File "/home/sucess/anaconda3/lib/python3.7/site-packages/dvc/external_repo.py", line 165, in _cached_clone
    clone_path, shallow = _clone_default_branch(url, rev, for_write=for_write)
  File "/home/sucess/anaconda3/lib/python3.7/site-packages/funcy/decorators.py", line 45, in wrapper
    return deco(call, *dargs, **dkwargs)
  File "/home/sucess/anaconda3/lib/python3.7/site-packages/funcy/flow.py", line 274, in wrap_with
    return call()
  File "/home/sucess/anaconda3/lib/python3.7/site-packages/funcy/decorators.py", line 66, in __call__
    return self._func(*self._args, **self._kwargs)
  File "/home/sucess/anaconda3/lib/python3.7/site-packages/dvc/external_repo.py", line 235, in _clone_default_branch
    git = clone(url, clone_path)
  File "/home/sucess/anaconda3/lib/python3.7/site-packages/dvc/scm.py", line 131, in clone
    raise CloneError(str(exc))
dvc.scm.CloneError: Failed to clone repo 'Pharmaceutical_sales_prediction' to '/tmp/tmp0ui4smvtdvc-clone'
2022-09-08 10:52:36,238 — FileHandler — ERROR — DVC data getter raised an exception
Traceback (most recent call last):
  File "/home/sucess/anaconda3/lib/python3.7/site-packages/scmrepo/git/backend/dulwich/__init__.py", line 193, in clone
    repo = clone_from()
  File "/home/sucess/anaconda3/lib/python3.7/site-packages/dulwich/porcelain.py", line 547, in clone
    depth=depth,
  File "/home/sucess/anaconda3/lib/python3.7/site-packages/dulwich/client.py", line 760, in clone
    result = self.fetch(path, target, progress=progress, depth=depth)
  File "/home/sucess/anaconda3/lib/python3.7/site-packages/dulwich/client.py", line 1501, in fetch
    with self._open_repo(path) as r:
  File "/home/sucess/anaconda3/lib/python3.7/site-packages/dulwich/client.py", line 1423, in _open_repo
    return closing(Repo(path))
  File "/home/sucess/anaconda3/lib/python3.7/site-packages/dulwich/repo.py", line 1091, in __init__
    "No git repository was found at %(path)s" % dict(path=root)
dulwich.errors.NotGitRepository: No git repository was found at Pharmaceutical_sales_prediction

The above exception was the direct cause of the following exception:

Traceback (most recent call last):
  File "/home/sucess/anaconda3/lib/python3.7/site-packages/dvc/scm.py", line 126, in clone
    git = Git.clone(url, to_path, progress=pbar.update_git, **kwargs)
  File "/home/sucess/anaconda3/lib/python3.7/site-packages/scmrepo/git/__init__.py", line 143, in clone
    backend.clone(url, to_path, **kwargs)
  File "/home/sucess/anaconda3/lib/python3.7/site-packages/scmrepo/git/backend/dulwich/__init__.py", line 196, in clone
    raise CloneError(url, to_path) from exc
scmrepo.exceptions.CloneError: Failed to clone repo 'Pharmaceutical_sales_prediction' to '/tmp/tmpu4jja1nydvc-clone'

During handling of the above exception, another exception occurred:

Traceback (most recent call last):
  File "../src/file_handler.py", line 57, in dvc_get_data
    rev=version)
  File "/home/sucess/anaconda3/lib/python3.7/site-packages/dvc/api.py", line 89, in read
    path, repo=repo, rev=rev, remote=remote, mode=mode, encoding=encoding
  File "/home/sucess/anaconda3/lib/python3.7/contextlib.py", line 112, in __enter__
    return next(self.gen)
  File "/home/sucess/anaconda3/lib/python3.7/site-packages/dvc/api.py", line 75, in _open
    with Repo.open(repo, rev=rev, subrepos=True, uninitialized=True) as _repo:
  File "/home/sucess/anaconda3/lib/python3.7/contextlib.py", line 112, in __enter__
    return next(self.gen)
  File "/home/sucess/anaconda3/lib/python3.7/site-packages/dvc/external_repo.py", line 39, in external_repo
    path = _cached_clone(url, rev, for_write=for_write)
  File "/home/sucess/anaconda3/lib/python3.7/site-packages/dvc/external_repo.py", line 165, in _cached_clone
    clone_path, shallow = _clone_default_branch(url, rev, for_write=for_write)
  File "/home/sucess/anaconda3/lib/python3.7/site-packages/funcy/decorators.py", line 45, in wrapper
    return deco(call, *dargs, **dkwargs)
  File "/home/sucess/anaconda3/lib/python3.7/site-packages/funcy/flow.py", line 274, in wrap_with
    return call()
  File "/home/sucess/anaconda3/lib/python3.7/site-packages/funcy/decorators.py", line 66, in __call__
    return self._func(*self._args, **self._kwargs)
  File "/home/sucess/anaconda3/lib/python3.7/site-packages/dvc/external_repo.py", line 235, in _clone_default_branch
    git = clone(url, clone_path)
  File "/home/sucess/anaconda3/lib/python3.7/site-packages/dvc/scm.py", line 131, in clone
    raise CloneError(str(exc))
dvc.scm.CloneError: Failed to clone repo 'Pharmaceutical_sales_prediction' to '/tmp/tmpu4jja1nydvc-clone'
2022-09-08 10:59:04,426 — FileHandler — ERROR — DVC data getter raised an exception
Traceback (most recent call last):
  File "../src/file_handler.py", line 57, in dvc_get_data
    rev=version)
  File "/home/sucess/anaconda3/lib/python3.7/site-packages/dvc/api.py", line 89, in read
    path, repo=repo, rev=rev, remote=remote, mode=mode, encoding=encoding
  File "/home/sucess/anaconda3/lib/python3.7/contextlib.py", line 112, in __enter__
    return next(self.gen)
  File "/home/sucess/anaconda3/lib/python3.7/site-packages/dvc/api.py", line 75, in _open
    with Repo.open(repo, rev=rev, subrepos=True, uninitialized=True) as _repo:
  File "/home/sucess/anaconda3/lib/python3.7/contextlib.py", line 112, in __enter__
    return next(self.gen)
  File "/home/sucess/anaconda3/lib/python3.7/site-packages/dvc/external_repo.py", line 39, in external_repo
    path = _cached_clone(url, rev, for_write=for_write)
  File "/home/sucess/anaconda3/lib/python3.7/site-packages/dvc/external_repo.py", line 165, in _cached_clone
    clone_path, shallow = _clone_default_branch(url, rev, for_write=for_write)
  File "/home/sucess/anaconda3/lib/python3.7/site-packages/funcy/decorators.py", line 45, in wrapper
    return deco(call, *dargs, **dkwargs)
  File "/home/sucess/anaconda3/lib/python3.7/site-packages/funcy/flow.py", line 274, in wrap_with
    return call()
  File "/home/sucess/anaconda3/lib/python3.7/site-packages/funcy/decorators.py", line 66, in __call__
    return self._func(*self._args, **self._kwargs)
  File "/home/sucess/anaconda3/lib/python3.7/site-packages/dvc/external_repo.py", line 235, in _clone_default_branch
    git = clone(url, clone_path)
  File "/home/sucess/anaconda3/lib/python3.7/site-packages/dvc/scm.py", line 126, in clone
    git = Git.clone(url, to_path, progress=pbar.update_git, **kwargs)
  File "/home/sucess/anaconda3/lib/python3.7/site-packages/scmrepo/git/__init__.py", line 143, in clone
    backend.clone(url, to_path, **kwargs)
  File "/home/sucess/anaconda3/lib/python3.7/site-packages/scmrepo/git/backend/dulwich/__init__.py", line 193, in clone
    repo = clone_from()
  File "/home/sucess/anaconda3/lib/python3.7/site-packages/dulwich/porcelain.py", line 547, in clone
    depth=depth,
  File "/home/sucess/anaconda3/lib/python3.7/site-packages/dulwich/client.py", line 760, in clone
    result = self.fetch(path, target, progress=progress, depth=depth)
  File "/home/sucess/anaconda3/lib/python3.7/site-packages/dulwich/client.py", line 843, in fetch
    depth=depth,
  File "/home/sucess/anaconda3/lib/python3.7/site-packages/dulwich/client.py", line 2116, in fetch_pack
    progress,
  File "/home/sucess/anaconda3/lib/python3.7/site-packages/dulwich/client.py", line 633, in _handle_upload_pack_tail
    SIDE_BAND_CHANNEL_PROGRESS: progress,
  File "/home/sucess/anaconda3/lib/python3.7/site-packages/dulwich/client.py", line 509, in _read_side_band64k_data
    for pkt in pkt_seq:
  File "/home/sucess/anaconda3/lib/python3.7/site-packages/dulwich/protocol.py", line 292, in read_pkt_seq
    pkt = self.read_pkt_line()
  File "/home/sucess/anaconda3/lib/python3.7/site-packages/dulwich/protocol.py", line 240, in read_pkt_line
    pkt_contents = read(size - 4)
  File "/home/sucess/anaconda3/lib/python3.7/site-packages/urllib3/response.py", line 566, in read
    data = self._fp_read(amt) if not fp_closed else b""
  File "/home/sucess/anaconda3/lib/python3.7/site-packages/urllib3/response.py", line 532, in _fp_read
    return self._fp.read(amt) if amt is not None else self._fp.read()
  File "/home/sucess/anaconda3/lib/python3.7/http/client.py", line 447, in read
    n = self.readinto(b)
  File "/home/sucess/anaconda3/lib/python3.7/http/client.py", line 481, in readinto
    return self._readinto_chunked(b)
  File "/home/sucess/anaconda3/lib/python3.7/http/client.py", line 581, in _readinto_chunked
    n = self._safe_readinto(mvb)
  File "/home/sucess/anaconda3/lib/python3.7/http/client.py", line 626, in _safe_readinto
    n = self.fp.readinto(mvb)
  File "/home/sucess/anaconda3/lib/python3.7/socket.py", line 589, in readinto
    return self._sock.recv_into(b)
  File "/home/sucess/anaconda3/lib/python3.7/ssl.py", line 1049, in recv_into
    return self.read(nbytes, buffer)
  File "/home/sucess/anaconda3/lib/python3.7/ssl.py", line 908, in read
    return self._sslobj.read(len, buffer)
KeyboardInterrupt
2022-09-08 11:05:38,808 — FileHandler — INFO — DVC: CSV file read with path: data/train.csv | version: v3 | from: ../
2022-09-08 11:05:38,834 — FileHandler — ERROR — DVC data getter raised an exception
Traceback (most recent call last):
  File "/home/sucess/anaconda3/lib/python3.7/site-packages/dvc/fs/dvc.py", line 114, in info
    outs = list(self.repo.index.tree.iteritems(key))
  File "/home/sucess/anaconda3/lib/python3.7/site-packages/dvc/data/tree.py", line 92, in iteritems
    for key, (meta, hash_info) in self._trie.iteritems(**kwargs):
  File "/home/sucess/anaconda3/lib/python3.7/site-packages/pygtrie.py", line 718, in iteritems
    node, _ = self._get_node(prefix)
  File "/home/sucess/anaconda3/lib/python3.7/site-packages/pygtrie.py", line 630, in _get_node
    raise KeyError(key)
KeyError: ('repo', '..', 'data', 'test.csv')

The above exception was the direct cause of the following exception:

Traceback (most recent call last):
  File "/home/sucess/anaconda3/lib/python3.7/site-packages/dvc/repo/__init__.py", line 499, in open_by_relpath
    path, mode=mode, encoding=encoding, remote=remote
  File "/home/sucess/anaconda3/lib/python3.7/site-packages/dvc/fs/base.py", line 186, in open
    return self.fs.open(path, mode=mode, encoding=encoding, **kwargs)
  File "/home/sucess/anaconda3/lib/python3.7/site-packages/dvc/fs/repo.py", line 309, in open
    return dvc_fs.open(dvc_path, mode=mode, encoding=encoding, **kwargs)
  File "/home/sucess/anaconda3/lib/python3.7/site-packages/dvc/fs/base.py", line 186, in open
    return self.fs.open(path, mode=mode, encoding=encoding, **kwargs)
  File "/home/sucess/anaconda3/lib/python3.7/site-packages/dvc/fs/dvc.py", line 77, in open
    fs, fspath = self._get_fs_path(path, **kwargs)
  File "/home/sucess/anaconda3/lib/python3.7/site-packages/dvc/fs/dvc.py", line 54, in _get_fs_path
    info = self.info(path)
  File "/home/sucess/anaconda3/lib/python3.7/site-packages/dvc/fs/dvc.py", line 116, in info
    raise FileNotFoundError from exc
FileNotFoundError

The above exception was the direct cause of the following exception:

Traceback (most recent call last):
  File "../src/file_handler.py", line 57, in dvc_get_data
    rev=version)
  File "/home/sucess/anaconda3/lib/python3.7/site-packages/dvc/api.py", line 89, in read
    path, repo=repo, rev=rev, remote=remote, mode=mode, encoding=encoding
  File "/home/sucess/anaconda3/lib/python3.7/contextlib.py", line 112, in __enter__
    return next(self.gen)
  File "/home/sucess/anaconda3/lib/python3.7/site-packages/dvc/api.py", line 77, in _open
    path, remote=remote, mode=mode, encoding=encoding
  File "/home/sucess/anaconda3/lib/python3.7/contextlib.py", line 112, in __enter__
    return next(self.gen)
  File "/home/sucess/anaconda3/lib/python3.7/site-packages/dvc/repo/__init__.py", line 503, in open_by_relpath
    raise FileMissingError(path) from exc
dvc.exceptions.FileMissingError: Can't find '../data/test.csv' neither locally nor on remote
2022-09-08 11:06:11,650 — FileHandler — INFO — DVC: CSV file read with path: data/train.csv | version: v3 | from: ../
2022-09-08 11:06:11,735 — FileHandler — INFO — DVC: CSV file read with path: data/test.csv | version: v5 | from: ../
2022-09-08 11:07:48,963 — FileHandler — INFO — DVC: CSV file read with path: data/train.csv | version: v3 | from: ../
2022-09-08 11:07:49,112 — FileHandler — INFO — DVC: CSV file read with path: data/test.csv | version: v5 | from: ../
2022-09-08 11:13:24,758 — FileHandler — INFO — DVC: CSV file read with path: data/train.csv | version: v3 | from: ../
2022-09-08 11:13:24,840 — FileHandler — INFO — DVC: CSV file read with path: data/test.csv | version: v5 | from: ../
2022-09-08 11:18:11,520 — FileHandler — INFO — DVC: CSV file read with path: data/train.csv | version: v3 | from: ../
2022-09-08 11:18:11,591 — FileHandler — INFO — DVC: CSV file read with path: data/test.csv | version: v5 | from: ../
2022-09-08 11:18:11,662 — FileHandler — INFO — DVC: CSV file read with path: data/store.csv | version: vs | from: ../
2022-09-08 11:22:04,397 — FileHandler — INFO — DVC: CSV file read with path: data/train.csv | version: v3 | from: ../
2022-09-08 11:22:04,474 — FileHandler — INFO — DVC: CSV file read with path: data/test.csv | version: v5 | from: ../
2022-09-08 11:22:04,503 — FileHandler — INFO — DVC: CSV file read with path: data/store.csv | version: vs | from: ../
2022-09-08 12:01:46,650 — FileHandler — INFO — DVC: CSV file read with path: data/train.csv | version: v3 | from: ../
2022-09-08 12:01:46,920 — FileHandler — INFO — DVC: CSV file read with path: data/test.csv | version: v5 | from: ../
2022-09-08 12:01:46,947 — FileHandler — INFO — DVC: CSV file read with path: data/store.csv | version: vs | from: ../
2022-09-08 12:02:55,622 — FileHandler — INFO — DVC: CSV file read with path: data/train.csv | version: v3 | from: ../
2022-09-08 12:02:55,897 — FileHandler — INFO — DVC: CSV file read with path: data/test.csv | version: v5 | from: ../
2022-09-08 12:02:55,922 — FileHandler — INFO — DVC: CSV file read with path: data/store.csv | version: vs | from: ../
2022-09-08 12:04:02,358 — FileHandler — INFO — DVC: CSV file read with path: data/train.csv | version: v3 | from: ../
2022-09-08 12:04:02,544 — FileHandler — INFO — DVC: CSV file read with path: data/test.csv | version: v5 | from: ../
2022-09-08 12:04:02,574 — FileHandler — INFO — DVC: CSV file read with path: data/store.csv | version: vs | from: ../
2022-09-08 12:04:45,125 — FileHandler — INFO — DVC: CSV file read with path: data/train.csv | version: v3 | from: ../
2022-09-08 12:04:45,183 — FileHandler — INFO — DVC: CSV file read with path: data/test.csv | version: v5 | from: ../
2022-09-08 12:04:45,204 — FileHandler — INFO — DVC: CSV file read with path: data/store.csv | version: vs | from: ../
2022-09-08 12:07:29,265 — FileHandler — INFO — DVC: CSV file read with path: data/train.csv | version: v3 | from: ../
2022-09-08 12:07:29,345 — FileHandler — INFO — DVC: CSV file read with path: data/test.csv | version: v5 | from: ../
2022-09-08 12:07:29,368 — FileHandler — INFO — DVC: CSV file read with path: data/store.csv | version: vs | from: ../
2022-09-08 12:53:32,050 — FileHandler — INFO — DVC: CSV file read with path: data/train.csv | version: v3 | from: ../
2022-09-08 12:53:32,106 — FileHandler — INFO — DVC: CSV file read with path: data/test.csv | version: v5 | from: ../
2022-09-08 12:53:32,133 — FileHandler — INFO — DVC: CSV file read with path: data/store.csv | version: vs | from: ../
2022-09-08 12:56:14,509 — FileHandler — INFO — DVC: CSV file read with path: data/train.csv | version: v3 | from: ../
2022-09-08 12:56:14,574 — FileHandler — INFO — DVC: CSV file read with path: data/test.csv | version: v5 | from: ../
2022-09-08 12:56:14,595 — FileHandler — INFO — DVC: CSV file read with path: data/store.csv | version: vs | from: ../
2022-09-08 12:56:36,441 — FileHandler — INFO — DVC: CSV file read with path: data/train.csv | version: v3 | from: ../
2022-09-08 12:56:36,498 — FileHandler — INFO — DVC: CSV file read with path: data/test.csv | version: v5 | from: ../
2022-09-08 12:56:36,521 — FileHandler — INFO — DVC: CSV file read with path: data/store.csv | version: vs | from: ../
2022-09-08 12:58:10,711 — FileHandler — INFO — DVC: CSV file read with path: data/train.csv | version: v3 | from: ../
2022-09-08 12:58:10,791 — FileHandler — INFO — DVC: CSV file read with path: data/test.csv | version: v5 | from: ../
2022-09-08 12:58:10,828 — FileHandler — INFO — DVC: CSV file read with path: data/store.csv | version: vs | from: ../
2022-09-08 12:58:28,240 — FileHandler — INFO — DVC: CSV file read with path: data/train.csv | version: v3 | from: ../
2022-09-08 12:58:28,375 — FileHandler — INFO — DVC: CSV file read with path: data/test.csv | version: v5 | from: ../
2022-09-08 12:58:28,401 — FileHandler — INFO — DVC: CSV file read with path: data/store.csv | version: vs | from: ../
2022-09-08 13:00:48,474 — FileHandler — INFO — DVC: CSV file read with path: data/train.csv | version: v3 | from: ../
2022-09-08 13:00:48,567 — FileHandler — INFO — DVC: CSV file read with path: data/test.csv | version: v5 | from: ../
2022-09-08 13:00:48,597 — FileHandler — INFO — DVC: CSV file read with path: data/store.csv | version: vs | from: ../
2022-09-08 13:03:56,702 — FileHandler — INFO — DVC: CSV file read with path: data/train.csv | version: v3 | from: ../
2022-09-08 13:03:56,915 — FileHandler — INFO — DVC: CSV file read with path: data/test.csv | version: v5 | from: ../
2022-09-08 13:03:56,972 — FileHandler — INFO — DVC: CSV file read with path: data/store.csv | version: vs | from: ../
2022-09-08 13:04:42,742 — FileHandler — INFO — DVC: CSV file read with path: data/train.csv | version: v3 | from: ../
2022-09-08 13:04:42,810 — FileHandler — INFO — DVC: CSV file read with path: data/test.csv | version: v5 | from: ../
2022-09-08 13:04:42,833 — FileHandler — INFO — DVC: CSV file read with path: data/store.csv | version: vs | from: ../
2022-09-08 13:23:15,816 — FileHandler — INFO — DVC: CSV file read with path: data/train.csv | version: v3 | from: ../
2022-09-08 13:23:15,919 — FileHandler — INFO — DVC: CSV file read with path: data/test.csv | version: v5 | from: ../
2022-09-08 13:23:15,956 — FileHandler — INFO — DVC: CSV file read with path: data/store.csv | version: vs | from: ../
2022-09-08 13:37:20,511 — FileHandler — INFO — DVC: CSV file read with path: data/train.csv | version: v3 | from: ../
2022-09-08 13:37:20,979 — FileHandler — INFO — DVC: CSV file read with path: data/test.csv | version: v5 | from: ../
2022-09-08 13:37:21,008 — FileHandler — INFO — DVC: CSV file read with path: data/store.csv | version: vs | from: ../
2022-09-08 15:28:04,104 — FileHandler — INFO — DVC: CSV file read with path: data/train.csv | version: v3 | from: ../
2022-09-08 15:28:04,210 — FileHandler — INFO — DVC: CSV file read with path: data/test.csv | version: v5 | from: ../
2022-09-08 15:28:04,318 — FileHandler — INFO — DVC: CSV file read with path: data/store.csv | version: vs | from: ../
2022-09-08 15:29:16,830 — FileHandler — INFO — DVC: CSV file read with path: data/train.csv | version: v3 | from: ../
2022-09-08 15:29:16,903 — FileHandler — INFO — DVC: CSV file read with path: data/test.csv | version: v5 | from: ../
2022-09-08 15:29:16,932 — FileHandler — INFO — DVC: CSV file read with path: data/store.csv | version: vs | from: ../
2022-09-08 15:54:48,607 — FileHandler — INFO — DVC: CSV file read with path: data/train.csv | version: v3 | from: ../
2022-09-08 15:54:48,676 — FileHandler — INFO — DVC: CSV file read with path: data/test.csv | version: v5 | from: ../
2022-09-08 15:54:48,702 — FileHandler — INFO — DVC: CSV file read with path: data/store.csv | version: vs | from: ../
2022-09-08 15:56:07,310 — FileHandler — INFO — DVC: CSV file read with path: data/train.csv | version: v3 | from: ../
2022-09-08 15:56:07,385 — FileHandler — INFO — DVC: CSV file read with path: data/test.csv | version: v5 | from: ../
2022-09-08 15:56:07,417 — FileHandler — INFO — DVC: CSV file read with path: data/store.csv | version: vs | from: ../
2022-09-08 17:01:24,672 — FileHandler — INFO — DVC: CSV file read with path: data/train.csv | version: v3 | from: ../
2022-09-08 17:01:24,741 — FileHandler — INFO — DVC: CSV file read with path: data/test.csv | version: v5 | from: ../
2022-09-08 17:01:24,767 — FileHandler — INFO — DVC: CSV file read with path: data/store.csv | version: vs | from: ../
