2022-09-09 07:22:23,644 — FileHandler — INFO — DVC: CSV file read with path: data/train.csv | version: v3 | from: ../
2022-09-09 07:22:24,260 — FileHandler — INFO — DVC: CSV file read with path: data/test.csv | version: v5 | from: ../
2022-09-09 07:22:24,357 — FileHandler — INFO — DVC: CSV file read with path: data/store.csv | version: vs | from: ../
2022-09-09 07:42:30,570 — FileHandler — ERROR — DVC data getter raised an exception
Traceback (most recent call last):
  File "/home/sucess/anaconda3/lib/python3.7/site-packages/dvc/fs/dvc.py", line 114, in info
    outs = list(self.repo.index.tree.iteritems(key))
  File "/home/sucess/anaconda3/lib/python3.7/site-packages/dvc/data/tree.py", line 92, in iteritems
    for key, (meta, hash_info) in self._trie.iteritems(**kwargs):
  File "/home/sucess/anaconda3/lib/python3.7/site-packages/pygtrie.py", line 718, in iteritems
    node, _ = self._get_node(prefix)
  File "/home/sucess/anaconda3/lib/python3.7/site-packages/pygtrie.py", line 630, in _get_node
    raise KeyError(key)
KeyError: ('repo', 'data', 'train_store.csv')

The above exception was the direct cause of the following exception:

Traceback (most recent call last):
  File "/home/sucess/anaconda3/lib/python3.7/site-packages/dvc/repo/__init__.py", line 499, in open_by_relpath
    path, mode=mode, encoding=encoding, remote=remote
  File "/home/sucess/anaconda3/lib/python3.7/site-packages/dvc/fs/base.py", line 186, in open
    return self.fs.open(path, mode=mode, encoding=encoding, **kwargs)
  File "/home/sucess/anaconda3/lib/python3.7/site-packages/dvc/fs/repo.py", line 309, in open
    return dvc_fs.open(dvc_path, mode=mode, encoding=encoding, **kwargs)
  File "/home/sucess/anaconda3/lib/python3.7/site-packages/dvc/fs/base.py", line 186, in open
    return self.fs.open(path, mode=mode, encoding=encoding, **kwargs)
  File "/home/sucess/anaconda3/lib/python3.7/site-packages/dvc/fs/dvc.py", line 77, in open
    fs, fspath = self._get_fs_path(path, **kwargs)
  File "/home/sucess/anaconda3/lib/python3.7/site-packages/dvc/fs/dvc.py", line 54, in _get_fs_path
    info = self.info(path)
  File "/home/sucess/anaconda3/lib/python3.7/site-packages/dvc/fs/dvc.py", line 116, in info
    raise FileNotFoundError from exc
FileNotFoundError

The above exception was the direct cause of the following exception:

Traceback (most recent call last):
  File "../src/file_handler.py", line 25, in dvc_get_data
    rev=version)
  File "/home/sucess/anaconda3/lib/python3.7/site-packages/dvc/api.py", line 89, in read
    path, repo=repo, rev=rev, remote=remote, mode=mode, encoding=encoding
  File "/home/sucess/anaconda3/lib/python3.7/contextlib.py", line 112, in __enter__
    return next(self.gen)
  File "/home/sucess/anaconda3/lib/python3.7/site-packages/dvc/api.py", line 77, in _open
    path, remote=remote, mode=mode, encoding=encoding
  File "/home/sucess/anaconda3/lib/python3.7/contextlib.py", line 112, in __enter__
    return next(self.gen)
  File "/home/sucess/anaconda3/lib/python3.7/site-packages/dvc/repo/__init__.py", line 503, in open_by_relpath
    raise FileMissingError(path) from exc
dvc.exceptions.FileMissingError: Can't find 'data/train_store.csv' neither locally nor on remote
2022-09-09 07:42:31,006 — FileHandler — ERROR — DVC data getter raised an exception
Traceback (most recent call last):
  File "/home/sucess/anaconda3/lib/python3.7/site-packages/dvc/fs/dvc.py", line 114, in info
    outs = list(self.repo.index.tree.iteritems(key))
  File "/home/sucess/anaconda3/lib/python3.7/site-packages/dvc/data/tree.py", line 92, in iteritems
    for key, (meta, hash_info) in self._trie.iteritems(**kwargs):
  File "/home/sucess/anaconda3/lib/python3.7/site-packages/pygtrie.py", line 718, in iteritems
    node, _ = self._get_node(prefix)
  File "/home/sucess/anaconda3/lib/python3.7/site-packages/pygtrie.py", line 630, in _get_node
    raise KeyError(key)
KeyError: ('repo', 'data', 'test_store.csv')

The above exception was the direct cause of the following exception:

Traceback (most recent call last):
  File "/home/sucess/anaconda3/lib/python3.7/site-packages/dvc/repo/__init__.py", line 499, in open_by_relpath
    path, mode=mode, encoding=encoding, remote=remote
  File "/home/sucess/anaconda3/lib/python3.7/site-packages/dvc/fs/base.py", line 186, in open
    return self.fs.open(path, mode=mode, encoding=encoding, **kwargs)
  File "/home/sucess/anaconda3/lib/python3.7/site-packages/dvc/fs/repo.py", line 309, in open
    return dvc_fs.open(dvc_path, mode=mode, encoding=encoding, **kwargs)
  File "/home/sucess/anaconda3/lib/python3.7/site-packages/dvc/fs/base.py", line 186, in open
    return self.fs.open(path, mode=mode, encoding=encoding, **kwargs)
  File "/home/sucess/anaconda3/lib/python3.7/site-packages/dvc/fs/dvc.py", line 77, in open
    fs, fspath = self._get_fs_path(path, **kwargs)
  File "/home/sucess/anaconda3/lib/python3.7/site-packages/dvc/fs/dvc.py", line 54, in _get_fs_path
    info = self.info(path)
  File "/home/sucess/anaconda3/lib/python3.7/site-packages/dvc/fs/dvc.py", line 116, in info
    raise FileNotFoundError from exc
FileNotFoundError

The above exception was the direct cause of the following exception:

Traceback (most recent call last):
  File "../src/file_handler.py", line 25, in dvc_get_data
    rev=version)
  File "/home/sucess/anaconda3/lib/python3.7/site-packages/dvc/api.py", line 89, in read
    path, repo=repo, rev=rev, remote=remote, mode=mode, encoding=encoding
  File "/home/sucess/anaconda3/lib/python3.7/contextlib.py", line 112, in __enter__
    return next(self.gen)
  File "/home/sucess/anaconda3/lib/python3.7/site-packages/dvc/api.py", line 77, in _open
    path, remote=remote, mode=mode, encoding=encoding
  File "/home/sucess/anaconda3/lib/python3.7/contextlib.py", line 112, in __enter__
    return next(self.gen)
  File "/home/sucess/anaconda3/lib/python3.7/site-packages/dvc/repo/__init__.py", line 503, in open_by_relpath
    raise FileMissingError(path) from exc
dvc.exceptions.FileMissingError: Can't find 'data/test_store.csv' neither locally nor on remote
2022-09-09 07:43:50,489 — FileHandler — INFO — DVC: CSV file read with path: data/train.csv | version: v3 | from: ../
2022-09-09 07:43:50,561 — FileHandler — INFO — DVC: CSV file read with path: data/test.csv | version: v5 | from: ../
2022-09-09 07:43:50,594 — FileHandler — INFO — DVC: CSV file read with path: data/store.csv | version: vs | from: ../
2022-09-09 07:44:18,552 — FileHandler — ERROR — DVC data getter raised an exception
Traceback (most recent call last):
  File "/home/sucess/anaconda3/lib/python3.7/site-packages/dvc/fs/dvc.py", line 114, in info
    outs = list(self.repo.index.tree.iteritems(key))
  File "/home/sucess/anaconda3/lib/python3.7/site-packages/dvc/data/tree.py", line 92, in iteritems
    for key, (meta, hash_info) in self._trie.iteritems(**kwargs):
  File "/home/sucess/anaconda3/lib/python3.7/site-packages/pygtrie.py", line 718, in iteritems
    node, _ = self._get_node(prefix)
  File "/home/sucess/anaconda3/lib/python3.7/site-packages/pygtrie.py", line 630, in _get_node
    raise KeyError(key)
KeyError: ('repo', 'data', 'train_store.csv')

The above exception was the direct cause of the following exception:

Traceback (most recent call last):
  File "/home/sucess/anaconda3/lib/python3.7/site-packages/dvc/repo/__init__.py", line 499, in open_by_relpath
    path, mode=mode, encoding=encoding, remote=remote
  File "/home/sucess/anaconda3/lib/python3.7/site-packages/dvc/fs/base.py", line 186, in open
    return self.fs.open(path, mode=mode, encoding=encoding, **kwargs)
  File "/home/sucess/anaconda3/lib/python3.7/site-packages/dvc/fs/repo.py", line 309, in open
    return dvc_fs.open(dvc_path, mode=mode, encoding=encoding, **kwargs)
  File "/home/sucess/anaconda3/lib/python3.7/site-packages/dvc/fs/base.py", line 186, in open
    return self.fs.open(path, mode=mode, encoding=encoding, **kwargs)
  File "/home/sucess/anaconda3/lib/python3.7/site-packages/dvc/fs/dvc.py", line 77, in open
    fs, fspath = self._get_fs_path(path, **kwargs)
  File "/home/sucess/anaconda3/lib/python3.7/site-packages/dvc/fs/dvc.py", line 54, in _get_fs_path
    info = self.info(path)
  File "/home/sucess/anaconda3/lib/python3.7/site-packages/dvc/fs/dvc.py", line 116, in info
    raise FileNotFoundError from exc
FileNotFoundError

The above exception was the direct cause of the following exception:

Traceback (most recent call last):
  File "../src/file_handler.py", line 25, in dvc_get_data
    rev=version)
  File "/home/sucess/anaconda3/lib/python3.7/site-packages/dvc/api.py", line 89, in read
    path, repo=repo, rev=rev, remote=remote, mode=mode, encoding=encoding
  File "/home/sucess/anaconda3/lib/python3.7/contextlib.py", line 112, in __enter__
    return next(self.gen)
  File "/home/sucess/anaconda3/lib/python3.7/site-packages/dvc/api.py", line 77, in _open
    path, remote=remote, mode=mode, encoding=encoding
  File "/home/sucess/anaconda3/lib/python3.7/contextlib.py", line 112, in __enter__
    return next(self.gen)
  File "/home/sucess/anaconda3/lib/python3.7/site-packages/dvc/repo/__init__.py", line 503, in open_by_relpath
    raise FileMissingError(path) from exc
dvc.exceptions.FileMissingError: Can't find 'data/train_store.csv' neither locally nor on remote
2022-09-09 07:44:18,600 — FileHandler — ERROR — DVC data getter raised an exception
Traceback (most recent call last):
  File "/home/sucess/anaconda3/lib/python3.7/site-packages/dvc/fs/dvc.py", line 114, in info
    outs = list(self.repo.index.tree.iteritems(key))
  File "/home/sucess/anaconda3/lib/python3.7/site-packages/dvc/data/tree.py", line 92, in iteritems
    for key, (meta, hash_info) in self._trie.iteritems(**kwargs):
  File "/home/sucess/anaconda3/lib/python3.7/site-packages/pygtrie.py", line 718, in iteritems
    node, _ = self._get_node(prefix)
  File "/home/sucess/anaconda3/lib/python3.7/site-packages/pygtrie.py", line 630, in _get_node
    raise KeyError(key)
KeyError: ('repo', 'data', 'test_store.csv')

The above exception was the direct cause of the following exception:

Traceback (most recent call last):
  File "/home/sucess/anaconda3/lib/python3.7/site-packages/dvc/repo/__init__.py", line 499, in open_by_relpath
    path, mode=mode, encoding=encoding, remote=remote
  File "/home/sucess/anaconda3/lib/python3.7/site-packages/dvc/fs/base.py", line 186, in open
    return self.fs.open(path, mode=mode, encoding=encoding, **kwargs)
  File "/home/sucess/anaconda3/lib/python3.7/site-packages/dvc/fs/repo.py", line 309, in open
    return dvc_fs.open(dvc_path, mode=mode, encoding=encoding, **kwargs)
  File "/home/sucess/anaconda3/lib/python3.7/site-packages/dvc/fs/base.py", line 186, in open
    return self.fs.open(path, mode=mode, encoding=encoding, **kwargs)
  File "/home/sucess/anaconda3/lib/python3.7/site-packages/dvc/fs/dvc.py", line 77, in open
    fs, fspath = self._get_fs_path(path, **kwargs)
  File "/home/sucess/anaconda3/lib/python3.7/site-packages/dvc/fs/dvc.py", line 54, in _get_fs_path
    info = self.info(path)
  File "/home/sucess/anaconda3/lib/python3.7/site-packages/dvc/fs/dvc.py", line 116, in info
    raise FileNotFoundError from exc
FileNotFoundError

The above exception was the direct cause of the following exception:

Traceback (most recent call last):
  File "../src/file_handler.py", line 25, in dvc_get_data
    rev=version)
  File "/home/sucess/anaconda3/lib/python3.7/site-packages/dvc/api.py", line 89, in read
    path, repo=repo, rev=rev, remote=remote, mode=mode, encoding=encoding
  File "/home/sucess/anaconda3/lib/python3.7/contextlib.py", line 112, in __enter__
    return next(self.gen)
  File "/home/sucess/anaconda3/lib/python3.7/site-packages/dvc/api.py", line 77, in _open
    path, remote=remote, mode=mode, encoding=encoding
  File "/home/sucess/anaconda3/lib/python3.7/contextlib.py", line 112, in __enter__
    return next(self.gen)
  File "/home/sucess/anaconda3/lib/python3.7/site-packages/dvc/repo/__init__.py", line 503, in open_by_relpath
    raise FileMissingError(path) from exc
dvc.exceptions.FileMissingError: Can't find 'data/test_store.csv' neither locally nor on remote
2022-09-09 07:44:56,008 — FileHandler — ERROR — DVC data getter raised an exception
Traceback (most recent call last):
  File "/home/sucess/anaconda3/lib/python3.7/site-packages/dvc/fs/dvc.py", line 114, in info
    outs = list(self.repo.index.tree.iteritems(key))
  File "/home/sucess/anaconda3/lib/python3.7/site-packages/dvc/data/tree.py", line 92, in iteritems
    for key, (meta, hash_info) in self._trie.iteritems(**kwargs):
  File "/home/sucess/anaconda3/lib/python3.7/site-packages/pygtrie.py", line 718, in iteritems
    node, _ = self._get_node(prefix)
  File "/home/sucess/anaconda3/lib/python3.7/site-packages/pygtrie.py", line 630, in _get_node
    raise KeyError(key)
KeyError: ('repo', '..', 'data', 'train_store.csv')

The above exception was the direct cause of the following exception:

Traceback (most recent call last):
  File "/home/sucess/anaconda3/lib/python3.7/site-packages/dvc/repo/__init__.py", line 499, in open_by_relpath
    path, mode=mode, encoding=encoding, remote=remote
  File "/home/sucess/anaconda3/lib/python3.7/site-packages/dvc/fs/base.py", line 186, in open
    return self.fs.open(path, mode=mode, encoding=encoding, **kwargs)
  File "/home/sucess/anaconda3/lib/python3.7/site-packages/dvc/fs/repo.py", line 309, in open
    return dvc_fs.open(dvc_path, mode=mode, encoding=encoding, **kwargs)
  File "/home/sucess/anaconda3/lib/python3.7/site-packages/dvc/fs/base.py", line 186, in open
    return self.fs.open(path, mode=mode, encoding=encoding, **kwargs)
  File "/home/sucess/anaconda3/lib/python3.7/site-packages/dvc/fs/dvc.py", line 77, in open
    fs, fspath = self._get_fs_path(path, **kwargs)
  File "/home/sucess/anaconda3/lib/python3.7/site-packages/dvc/fs/dvc.py", line 54, in _get_fs_path
    info = self.info(path)
  File "/home/sucess/anaconda3/lib/python3.7/site-packages/dvc/fs/dvc.py", line 116, in info
    raise FileNotFoundError from exc
FileNotFoundError

The above exception was the direct cause of the following exception:

Traceback (most recent call last):
  File "../src/file_handler.py", line 25, in dvc_get_data
    rev=version)
  File "/home/sucess/anaconda3/lib/python3.7/site-packages/dvc/api.py", line 89, in read
    path, repo=repo, rev=rev, remote=remote, mode=mode, encoding=encoding
  File "/home/sucess/anaconda3/lib/python3.7/contextlib.py", line 112, in __enter__
    return next(self.gen)
  File "/home/sucess/anaconda3/lib/python3.7/site-packages/dvc/api.py", line 77, in _open
    path, remote=remote, mode=mode, encoding=encoding
  File "/home/sucess/anaconda3/lib/python3.7/contextlib.py", line 112, in __enter__
    return next(self.gen)
  File "/home/sucess/anaconda3/lib/python3.7/site-packages/dvc/repo/__init__.py", line 503, in open_by_relpath
    raise FileMissingError(path) from exc
dvc.exceptions.FileMissingError: Can't find '../data/train_store.csv' neither locally nor on remote
2022-09-09 07:44:56,057 — FileHandler — ERROR — DVC data getter raised an exception
Traceback (most recent call last):
  File "/home/sucess/anaconda3/lib/python3.7/site-packages/dvc/fs/dvc.py", line 114, in info
    outs = list(self.repo.index.tree.iteritems(key))
  File "/home/sucess/anaconda3/lib/python3.7/site-packages/dvc/data/tree.py", line 92, in iteritems
    for key, (meta, hash_info) in self._trie.iteritems(**kwargs):
  File "/home/sucess/anaconda3/lib/python3.7/site-packages/pygtrie.py", line 718, in iteritems
    node, _ = self._get_node(prefix)
  File "/home/sucess/anaconda3/lib/python3.7/site-packages/pygtrie.py", line 630, in _get_node
    raise KeyError(key)
KeyError: ('repo', '..', 'data', 'test_store.csv')

The above exception was the direct cause of the following exception:

Traceback (most recent call last):
  File "/home/sucess/anaconda3/lib/python3.7/site-packages/dvc/repo/__init__.py", line 499, in open_by_relpath
    path, mode=mode, encoding=encoding, remote=remote
  File "/home/sucess/anaconda3/lib/python3.7/site-packages/dvc/fs/base.py", line 186, in open
    return self.fs.open(path, mode=mode, encoding=encoding, **kwargs)
  File "/home/sucess/anaconda3/lib/python3.7/site-packages/dvc/fs/repo.py", line 309, in open
    return dvc_fs.open(dvc_path, mode=mode, encoding=encoding, **kwargs)
  File "/home/sucess/anaconda3/lib/python3.7/site-packages/dvc/fs/base.py", line 186, in open
    return self.fs.open(path, mode=mode, encoding=encoding, **kwargs)
  File "/home/sucess/anaconda3/lib/python3.7/site-packages/dvc/fs/dvc.py", line 77, in open
    fs, fspath = self._get_fs_path(path, **kwargs)
  File "/home/sucess/anaconda3/lib/python3.7/site-packages/dvc/fs/dvc.py", line 54, in _get_fs_path
    info = self.info(path)
  File "/home/sucess/anaconda3/lib/python3.7/site-packages/dvc/fs/dvc.py", line 116, in info
    raise FileNotFoundError from exc
FileNotFoundError

The above exception was the direct cause of the following exception:

Traceback (most recent call last):
  File "../src/file_handler.py", line 25, in dvc_get_data
    rev=version)
  File "/home/sucess/anaconda3/lib/python3.7/site-packages/dvc/api.py", line 89, in read
    path, repo=repo, rev=rev, remote=remote, mode=mode, encoding=encoding
  File "/home/sucess/anaconda3/lib/python3.7/contextlib.py", line 112, in __enter__
    return next(self.gen)
  File "/home/sucess/anaconda3/lib/python3.7/site-packages/dvc/api.py", line 77, in _open
    path, remote=remote, mode=mode, encoding=encoding
  File "/home/sucess/anaconda3/lib/python3.7/contextlib.py", line 112, in __enter__
    return next(self.gen)
  File "/home/sucess/anaconda3/lib/python3.7/site-packages/dvc/repo/__init__.py", line 503, in open_by_relpath
    raise FileMissingError(path) from exc
dvc.exceptions.FileMissingError: Can't find '../data/test_store.csv' neither locally nor on remote
2022-09-09 07:45:23,791 — FileHandler — ERROR — DVC data getter raised an exception
Traceback (most recent call last):
  File "/home/sucess/anaconda3/lib/python3.7/site-packages/dvc/fs/dvc.py", line 114, in info
    outs = list(self.repo.index.tree.iteritems(key))
  File "/home/sucess/anaconda3/lib/python3.7/site-packages/dvc/data/tree.py", line 92, in iteritems
    for key, (meta, hash_info) in self._trie.iteritems(**kwargs):
  File "/home/sucess/anaconda3/lib/python3.7/site-packages/pygtrie.py", line 718, in iteritems
    node, _ = self._get_node(prefix)
  File "/home/sucess/anaconda3/lib/python3.7/site-packages/pygtrie.py", line 630, in _get_node
    raise KeyError(key)
KeyError: ('repo', 'data', 'train_store.csv')

The above exception was the direct cause of the following exception:

Traceback (most recent call last):
  File "/home/sucess/anaconda3/lib/python3.7/site-packages/dvc/repo/__init__.py", line 499, in open_by_relpath
    path, mode=mode, encoding=encoding, remote=remote
  File "/home/sucess/anaconda3/lib/python3.7/site-packages/dvc/fs/base.py", line 186, in open
    return self.fs.open(path, mode=mode, encoding=encoding, **kwargs)
  File "/home/sucess/anaconda3/lib/python3.7/site-packages/dvc/fs/repo.py", line 309, in open
    return dvc_fs.open(dvc_path, mode=mode, encoding=encoding, **kwargs)
  File "/home/sucess/anaconda3/lib/python3.7/site-packages/dvc/fs/base.py", line 186, in open
    return self.fs.open(path, mode=mode, encoding=encoding, **kwargs)
  File "/home/sucess/anaconda3/lib/python3.7/site-packages/dvc/fs/dvc.py", line 77, in open
    fs, fspath = self._get_fs_path(path, **kwargs)
  File "/home/sucess/anaconda3/lib/python3.7/site-packages/dvc/fs/dvc.py", line 54, in _get_fs_path
    info = self.info(path)
  File "/home/sucess/anaconda3/lib/python3.7/site-packages/dvc/fs/dvc.py", line 116, in info
    raise FileNotFoundError from exc
FileNotFoundError

The above exception was the direct cause of the following exception:

Traceback (most recent call last):
  File "../src/file_handler.py", line 25, in dvc_get_data
    rev=version)
  File "/home/sucess/anaconda3/lib/python3.7/site-packages/dvc/api.py", line 89, in read
    path, repo=repo, rev=rev, remote=remote, mode=mode, encoding=encoding
  File "/home/sucess/anaconda3/lib/python3.7/contextlib.py", line 112, in __enter__
    return next(self.gen)
  File "/home/sucess/anaconda3/lib/python3.7/site-packages/dvc/api.py", line 77, in _open
    path, remote=remote, mode=mode, encoding=encoding
  File "/home/sucess/anaconda3/lib/python3.7/contextlib.py", line 112, in __enter__
    return next(self.gen)
  File "/home/sucess/anaconda3/lib/python3.7/site-packages/dvc/repo/__init__.py", line 503, in open_by_relpath
    raise FileMissingError(path) from exc
dvc.exceptions.FileMissingError: Can't find 'data/train_store.csv' neither locally nor on remote
2022-09-09 07:45:23,879 — FileHandler — ERROR — DVC data getter raised an exception
Traceback (most recent call last):
  File "/home/sucess/anaconda3/lib/python3.7/site-packages/dvc/fs/dvc.py", line 114, in info
    outs = list(self.repo.index.tree.iteritems(key))
  File "/home/sucess/anaconda3/lib/python3.7/site-packages/dvc/data/tree.py", line 92, in iteritems
    for key, (meta, hash_info) in self._trie.iteritems(**kwargs):
  File "/home/sucess/anaconda3/lib/python3.7/site-packages/pygtrie.py", line 718, in iteritems
    node, _ = self._get_node(prefix)
  File "/home/sucess/anaconda3/lib/python3.7/site-packages/pygtrie.py", line 630, in _get_node
    raise KeyError(key)
KeyError: ('repo', 'data', 'test_store.csv')

The above exception was the direct cause of the following exception:

Traceback (most recent call last):
  File "/home/sucess/anaconda3/lib/python3.7/site-packages/dvc/repo/__init__.py", line 499, in open_by_relpath
    path, mode=mode, encoding=encoding, remote=remote
  File "/home/sucess/anaconda3/lib/python3.7/site-packages/dvc/fs/base.py", line 186, in open
    return self.fs.open(path, mode=mode, encoding=encoding, **kwargs)
  File "/home/sucess/anaconda3/lib/python3.7/site-packages/dvc/fs/repo.py", line 309, in open
    return dvc_fs.open(dvc_path, mode=mode, encoding=encoding, **kwargs)
  File "/home/sucess/anaconda3/lib/python3.7/site-packages/dvc/fs/base.py", line 186, in open
    return self.fs.open(path, mode=mode, encoding=encoding, **kwargs)
  File "/home/sucess/anaconda3/lib/python3.7/site-packages/dvc/fs/dvc.py", line 77, in open
    fs, fspath = self._get_fs_path(path, **kwargs)
  File "/home/sucess/anaconda3/lib/python3.7/site-packages/dvc/fs/dvc.py", line 54, in _get_fs_path
    info = self.info(path)
  File "/home/sucess/anaconda3/lib/python3.7/site-packages/dvc/fs/dvc.py", line 116, in info
    raise FileNotFoundError from exc
FileNotFoundError

The above exception was the direct cause of the following exception:

Traceback (most recent call last):
  File "../src/file_handler.py", line 25, in dvc_get_data
    rev=version)
  File "/home/sucess/anaconda3/lib/python3.7/site-packages/dvc/api.py", line 89, in read
    path, repo=repo, rev=rev, remote=remote, mode=mode, encoding=encoding
  File "/home/sucess/anaconda3/lib/python3.7/contextlib.py", line 112, in __enter__
    return next(self.gen)
  File "/home/sucess/anaconda3/lib/python3.7/site-packages/dvc/api.py", line 77, in _open
    path, remote=remote, mode=mode, encoding=encoding
  File "/home/sucess/anaconda3/lib/python3.7/contextlib.py", line 112, in __enter__
    return next(self.gen)
  File "/home/sucess/anaconda3/lib/python3.7/site-packages/dvc/repo/__init__.py", line 503, in open_by_relpath
    raise FileMissingError(path) from exc
dvc.exceptions.FileMissingError: Can't find 'data/test_store.csv' neither locally nor on remote
2022-09-09 07:45:52,562 — FileHandler — ERROR — DVC data getter raised an exception
Traceback (most recent call last):
  File "/home/sucess/anaconda3/lib/python3.7/site-packages/dvc/fs/dvc.py", line 114, in info
    outs = list(self.repo.index.tree.iteritems(key))
  File "/home/sucess/anaconda3/lib/python3.7/site-packages/dvc/data/tree.py", line 92, in iteritems
    for key, (meta, hash_info) in self._trie.iteritems(**kwargs):
  File "/home/sucess/anaconda3/lib/python3.7/site-packages/pygtrie.py", line 718, in iteritems
    node, _ = self._get_node(prefix)
  File "/home/sucess/anaconda3/lib/python3.7/site-packages/pygtrie.py", line 630, in _get_node
    raise KeyError(key)
KeyError: ('repo', 'data', 'train_store.csv')

The above exception was the direct cause of the following exception:

Traceback (most recent call last):
  File "/home/sucess/anaconda3/lib/python3.7/site-packages/dvc/repo/__init__.py", line 499, in open_by_relpath
    path, mode=mode, encoding=encoding, remote=remote
  File "/home/sucess/anaconda3/lib/python3.7/site-packages/dvc/fs/base.py", line 186, in open
    return self.fs.open(path, mode=mode, encoding=encoding, **kwargs)
  File "/home/sucess/anaconda3/lib/python3.7/site-packages/dvc/fs/repo.py", line 309, in open
    return dvc_fs.open(dvc_path, mode=mode, encoding=encoding, **kwargs)
  File "/home/sucess/anaconda3/lib/python3.7/site-packages/dvc/fs/base.py", line 186, in open
    return self.fs.open(path, mode=mode, encoding=encoding, **kwargs)
  File "/home/sucess/anaconda3/lib/python3.7/site-packages/dvc/fs/dvc.py", line 77, in open
    fs, fspath = self._get_fs_path(path, **kwargs)
  File "/home/sucess/anaconda3/lib/python3.7/site-packages/dvc/fs/dvc.py", line 54, in _get_fs_path
    info = self.info(path)
  File "/home/sucess/anaconda3/lib/python3.7/site-packages/dvc/fs/dvc.py", line 116, in info
    raise FileNotFoundError from exc
FileNotFoundError

The above exception was the direct cause of the following exception:

Traceback (most recent call last):
  File "../src/file_handler.py", line 25, in dvc_get_data
    rev=version)
  File "/home/sucess/anaconda3/lib/python3.7/site-packages/dvc/api.py", line 89, in read
    path, repo=repo, rev=rev, remote=remote, mode=mode, encoding=encoding
  File "/home/sucess/anaconda3/lib/python3.7/contextlib.py", line 112, in __enter__
    return next(self.gen)
  File "/home/sucess/anaconda3/lib/python3.7/site-packages/dvc/api.py", line 77, in _open
    path, remote=remote, mode=mode, encoding=encoding
  File "/home/sucess/anaconda3/lib/python3.7/contextlib.py", line 112, in __enter__
    return next(self.gen)
  File "/home/sucess/anaconda3/lib/python3.7/site-packages/dvc/repo/__init__.py", line 503, in open_by_relpath
    raise FileMissingError(path) from exc
dvc.exceptions.FileMissingError: Can't find 'data/train_store.csv' neither locally nor on remote
2022-09-09 07:45:52,615 — FileHandler — ERROR — DVC data getter raised an exception
Traceback (most recent call last):
  File "/home/sucess/anaconda3/lib/python3.7/site-packages/dvc/fs/dvc.py", line 114, in info
    outs = list(self.repo.index.tree.iteritems(key))
  File "/home/sucess/anaconda3/lib/python3.7/site-packages/dvc/data/tree.py", line 92, in iteritems
    for key, (meta, hash_info) in self._trie.iteritems(**kwargs):
  File "/home/sucess/anaconda3/lib/python3.7/site-packages/pygtrie.py", line 718, in iteritems
    node, _ = self._get_node(prefix)
  File "/home/sucess/anaconda3/lib/python3.7/site-packages/pygtrie.py", line 630, in _get_node
    raise KeyError(key)
KeyError: ('repo', 'data', 'test_store.csv')

The above exception was the direct cause of the following exception:

Traceback (most recent call last):
  File "/home/sucess/anaconda3/lib/python3.7/site-packages/dvc/repo/__init__.py", line 499, in open_by_relpath
    path, mode=mode, encoding=encoding, remote=remote
  File "/home/sucess/anaconda3/lib/python3.7/site-packages/dvc/fs/base.py", line 186, in open
    return self.fs.open(path, mode=mode, encoding=encoding, **kwargs)
  File "/home/sucess/anaconda3/lib/python3.7/site-packages/dvc/fs/repo.py", line 309, in open
    return dvc_fs.open(dvc_path, mode=mode, encoding=encoding, **kwargs)
  File "/home/sucess/anaconda3/lib/python3.7/site-packages/dvc/fs/base.py", line 186, in open
    return self.fs.open(path, mode=mode, encoding=encoding, **kwargs)
  File "/home/sucess/anaconda3/lib/python3.7/site-packages/dvc/fs/dvc.py", line 77, in open
    fs, fspath = self._get_fs_path(path, **kwargs)
  File "/home/sucess/anaconda3/lib/python3.7/site-packages/dvc/fs/dvc.py", line 54, in _get_fs_path
    info = self.info(path)
  File "/home/sucess/anaconda3/lib/python3.7/site-packages/dvc/fs/dvc.py", line 116, in info
    raise FileNotFoundError from exc
FileNotFoundError

The above exception was the direct cause of the following exception:

Traceback (most recent call last):
  File "../src/file_handler.py", line 25, in dvc_get_data
    rev=version)
  File "/home/sucess/anaconda3/lib/python3.7/site-packages/dvc/api.py", line 89, in read
    path, repo=repo, rev=rev, remote=remote, mode=mode, encoding=encoding
  File "/home/sucess/anaconda3/lib/python3.7/contextlib.py", line 112, in __enter__
    return next(self.gen)
  File "/home/sucess/anaconda3/lib/python3.7/site-packages/dvc/api.py", line 77, in _open
    path, remote=remote, mode=mode, encoding=encoding
  File "/home/sucess/anaconda3/lib/python3.7/contextlib.py", line 112, in __enter__
    return next(self.gen)
  File "/home/sucess/anaconda3/lib/python3.7/site-packages/dvc/repo/__init__.py", line 503, in open_by_relpath
    raise FileMissingError(path) from exc
dvc.exceptions.FileMissingError: Can't find 'data/test_store.csv' neither locally nor on remote
2022-09-09 07:46:44,427 — FileHandler — ERROR — DVC data getter raised an exception
Traceback (most recent call last):
  File "/home/sucess/anaconda3/lib/python3.7/site-packages/dvc/fs/dvc.py", line 114, in info
    outs = list(self.repo.index.tree.iteritems(key))
  File "/home/sucess/anaconda3/lib/python3.7/site-packages/dvc/data/tree.py", line 92, in iteritems
    for key, (meta, hash_info) in self._trie.iteritems(**kwargs):
  File "/home/sucess/anaconda3/lib/python3.7/site-packages/pygtrie.py", line 718, in iteritems
    node, _ = self._get_node(prefix)
  File "/home/sucess/anaconda3/lib/python3.7/site-packages/pygtrie.py", line 630, in _get_node
    raise KeyError(key)
KeyError: ('repo', 'data', 'train_store.csv')

The above exception was the direct cause of the following exception:

Traceback (most recent call last):
  File "/home/sucess/anaconda3/lib/python3.7/site-packages/dvc/repo/__init__.py", line 499, in open_by_relpath
    path, mode=mode, encoding=encoding, remote=remote
  File "/home/sucess/anaconda3/lib/python3.7/site-packages/dvc/fs/base.py", line 186, in open
    return self.fs.open(path, mode=mode, encoding=encoding, **kwargs)
  File "/home/sucess/anaconda3/lib/python3.7/site-packages/dvc/fs/repo.py", line 309, in open
    return dvc_fs.open(dvc_path, mode=mode, encoding=encoding, **kwargs)
  File "/home/sucess/anaconda3/lib/python3.7/site-packages/dvc/fs/base.py", line 186, in open
    return self.fs.open(path, mode=mode, encoding=encoding, **kwargs)
  File "/home/sucess/anaconda3/lib/python3.7/site-packages/dvc/fs/dvc.py", line 77, in open
    fs, fspath = self._get_fs_path(path, **kwargs)
  File "/home/sucess/anaconda3/lib/python3.7/site-packages/dvc/fs/dvc.py", line 54, in _get_fs_path
    info = self.info(path)
  File "/home/sucess/anaconda3/lib/python3.7/site-packages/dvc/fs/dvc.py", line 116, in info
    raise FileNotFoundError from exc
FileNotFoundError

The above exception was the direct cause of the following exception:

Traceback (most recent call last):
  File "../src/file_handler.py", line 25, in dvc_get_data
    rev=version)
  File "/home/sucess/anaconda3/lib/python3.7/site-packages/dvc/api.py", line 89, in read
    path, repo=repo, rev=rev, remote=remote, mode=mode, encoding=encoding
  File "/home/sucess/anaconda3/lib/python3.7/contextlib.py", line 112, in __enter__
    return next(self.gen)
  File "/home/sucess/anaconda3/lib/python3.7/site-packages/dvc/api.py", line 77, in _open
    path, remote=remote, mode=mode, encoding=encoding
  File "/home/sucess/anaconda3/lib/python3.7/contextlib.py", line 112, in __enter__
    return next(self.gen)
  File "/home/sucess/anaconda3/lib/python3.7/site-packages/dvc/repo/__init__.py", line 503, in open_by_relpath
    raise FileMissingError(path) from exc
dvc.exceptions.FileMissingError: Can't find 'data/train_store.csv' neither locally nor on remote
2022-09-09 07:46:44,467 — FileHandler — ERROR — DVC data getter raised an exception
Traceback (most recent call last):
  File "/home/sucess/anaconda3/lib/python3.7/site-packages/dvc/fs/dvc.py", line 114, in info
    outs = list(self.repo.index.tree.iteritems(key))
  File "/home/sucess/anaconda3/lib/python3.7/site-packages/dvc/data/tree.py", line 92, in iteritems
    for key, (meta, hash_info) in self._trie.iteritems(**kwargs):
  File "/home/sucess/anaconda3/lib/python3.7/site-packages/pygtrie.py", line 718, in iteritems
    node, _ = self._get_node(prefix)
  File "/home/sucess/anaconda3/lib/python3.7/site-packages/pygtrie.py", line 630, in _get_node
    raise KeyError(key)
KeyError: ('repo', 'data', 'test_store.csv')

The above exception was the direct cause of the following exception:

Traceback (most recent call last):
  File "/home/sucess/anaconda3/lib/python3.7/site-packages/dvc/repo/__init__.py", line 499, in open_by_relpath
    path, mode=mode, encoding=encoding, remote=remote
  File "/home/sucess/anaconda3/lib/python3.7/site-packages/dvc/fs/base.py", line 186, in open
    return self.fs.open(path, mode=mode, encoding=encoding, **kwargs)
  File "/home/sucess/anaconda3/lib/python3.7/site-packages/dvc/fs/repo.py", line 309, in open
    return dvc_fs.open(dvc_path, mode=mode, encoding=encoding, **kwargs)
  File "/home/sucess/anaconda3/lib/python3.7/site-packages/dvc/fs/base.py", line 186, in open
    return self.fs.open(path, mode=mode, encoding=encoding, **kwargs)
  File "/home/sucess/anaconda3/lib/python3.7/site-packages/dvc/fs/dvc.py", line 77, in open
    fs, fspath = self._get_fs_path(path, **kwargs)
  File "/home/sucess/anaconda3/lib/python3.7/site-packages/dvc/fs/dvc.py", line 54, in _get_fs_path
    info = self.info(path)
  File "/home/sucess/anaconda3/lib/python3.7/site-packages/dvc/fs/dvc.py", line 116, in info
    raise FileNotFoundError from exc
FileNotFoundError

The above exception was the direct cause of the following exception:

Traceback (most recent call last):
  File "../src/file_handler.py", line 25, in dvc_get_data
    rev=version)
  File "/home/sucess/anaconda3/lib/python3.7/site-packages/dvc/api.py", line 89, in read
    path, repo=repo, rev=rev, remote=remote, mode=mode, encoding=encoding
  File "/home/sucess/anaconda3/lib/python3.7/contextlib.py", line 112, in __enter__
    return next(self.gen)
  File "/home/sucess/anaconda3/lib/python3.7/site-packages/dvc/api.py", line 77, in _open
    path, remote=remote, mode=mode, encoding=encoding
  File "/home/sucess/anaconda3/lib/python3.7/contextlib.py", line 112, in __enter__
    return next(self.gen)
  File "/home/sucess/anaconda3/lib/python3.7/site-packages/dvc/repo/__init__.py", line 503, in open_by_relpath
    raise FileMissingError(path) from exc
dvc.exceptions.FileMissingError: Can't find 'data/test_store.csv' neither locally nor on remote
2022-09-09 07:47:56,342 — FileHandler — ERROR — DVC data getter raised an exception
Traceback (most recent call last):
  File "/home/sucess/anaconda3/lib/python3.7/site-packages/dvc/fs/dvc.py", line 114, in info
    outs = list(self.repo.index.tree.iteritems(key))
  File "/home/sucess/anaconda3/lib/python3.7/site-packages/dvc/data/tree.py", line 92, in iteritems
    for key, (meta, hash_info) in self._trie.iteritems(**kwargs):
  File "/home/sucess/anaconda3/lib/python3.7/site-packages/pygtrie.py", line 718, in iteritems
    node, _ = self._get_node(prefix)
  File "/home/sucess/anaconda3/lib/python3.7/site-packages/pygtrie.py", line 630, in _get_node
    raise KeyError(key)
KeyError: ('repo', 'data', 'train_store.csv')

The above exception was the direct cause of the following exception:

Traceback (most recent call last):
  File "/home/sucess/anaconda3/lib/python3.7/site-packages/dvc/repo/__init__.py", line 499, in open_by_relpath
    path, mode=mode, encoding=encoding, remote=remote
  File "/home/sucess/anaconda3/lib/python3.7/site-packages/dvc/fs/base.py", line 186, in open
    return self.fs.open(path, mode=mode, encoding=encoding, **kwargs)
  File "/home/sucess/anaconda3/lib/python3.7/site-packages/dvc/fs/repo.py", line 309, in open
    return dvc_fs.open(dvc_path, mode=mode, encoding=encoding, **kwargs)
  File "/home/sucess/anaconda3/lib/python3.7/site-packages/dvc/fs/base.py", line 186, in open
    return self.fs.open(path, mode=mode, encoding=encoding, **kwargs)
  File "/home/sucess/anaconda3/lib/python3.7/site-packages/dvc/fs/dvc.py", line 77, in open
    fs, fspath = self._get_fs_path(path, **kwargs)
  File "/home/sucess/anaconda3/lib/python3.7/site-packages/dvc/fs/dvc.py", line 54, in _get_fs_path
    info = self.info(path)
  File "/home/sucess/anaconda3/lib/python3.7/site-packages/dvc/fs/dvc.py", line 116, in info
    raise FileNotFoundError from exc
FileNotFoundError

The above exception was the direct cause of the following exception:

Traceback (most recent call last):
  File "../src/file_handler.py", line 25, in dvc_get_data
    rev=version)
  File "/home/sucess/anaconda3/lib/python3.7/site-packages/dvc/api.py", line 89, in read
    path, repo=repo, rev=rev, remote=remote, mode=mode, encoding=encoding
  File "/home/sucess/anaconda3/lib/python3.7/contextlib.py", line 112, in __enter__
    return next(self.gen)
  File "/home/sucess/anaconda3/lib/python3.7/site-packages/dvc/api.py", line 77, in _open
    path, remote=remote, mode=mode, encoding=encoding
  File "/home/sucess/anaconda3/lib/python3.7/contextlib.py", line 112, in __enter__
    return next(self.gen)
  File "/home/sucess/anaconda3/lib/python3.7/site-packages/dvc/repo/__init__.py", line 503, in open_by_relpath
    raise FileMissingError(path) from exc
dvc.exceptions.FileMissingError: Can't find 'data/train_store.csv' neither locally nor on remote
2022-09-09 07:47:56,426 — FileHandler — INFO — DVC: CSV file read with path: data/test.csv | version: v5 | from: ../
2022-09-09 07:47:56,464 — FileHandler — INFO — DVC: CSV file read with path: data/store.csv | version: vs | from: ../
2022-09-09 07:48:49,365 — FileHandler — ERROR — DVC data getter raised an exception
Traceback (most recent call last):
  File "/home/sucess/anaconda3/lib/python3.7/site-packages/dvc/fs/dvc.py", line 114, in info
    outs = list(self.repo.index.tree.iteritems(key))
  File "/home/sucess/anaconda3/lib/python3.7/site-packages/dvc/data/tree.py", line 92, in iteritems
    for key, (meta, hash_info) in self._trie.iteritems(**kwargs):
  File "/home/sucess/anaconda3/lib/python3.7/site-packages/pygtrie.py", line 718, in iteritems
    node, _ = self._get_node(prefix)
  File "/home/sucess/anaconda3/lib/python3.7/site-packages/pygtrie.py", line 630, in _get_node
    raise KeyError(key)
KeyError: ('repo', 'data', 'train_store.csv.dvc')

The above exception was the direct cause of the following exception:

Traceback (most recent call last):
  File "/home/sucess/anaconda3/lib/python3.7/site-packages/dvc/repo/__init__.py", line 499, in open_by_relpath
    path, mode=mode, encoding=encoding, remote=remote
  File "/home/sucess/anaconda3/lib/python3.7/site-packages/dvc/fs/base.py", line 186, in open
    return self.fs.open(path, mode=mode, encoding=encoding, **kwargs)
  File "/home/sucess/anaconda3/lib/python3.7/site-packages/dvc/fs/repo.py", line 309, in open
    return dvc_fs.open(dvc_path, mode=mode, encoding=encoding, **kwargs)
  File "/home/sucess/anaconda3/lib/python3.7/site-packages/dvc/fs/base.py", line 186, in open
    return self.fs.open(path, mode=mode, encoding=encoding, **kwargs)
  File "/home/sucess/anaconda3/lib/python3.7/site-packages/dvc/fs/dvc.py", line 77, in open
    fs, fspath = self._get_fs_path(path, **kwargs)
  File "/home/sucess/anaconda3/lib/python3.7/site-packages/dvc/fs/dvc.py", line 54, in _get_fs_path
    info = self.info(path)
  File "/home/sucess/anaconda3/lib/python3.7/site-packages/dvc/fs/dvc.py", line 116, in info
    raise FileNotFoundError from exc
FileNotFoundError

The above exception was the direct cause of the following exception:

Traceback (most recent call last):
  File "../src/file_handler.py", line 25, in dvc_get_data
    rev=version)
  File "/home/sucess/anaconda3/lib/python3.7/site-packages/dvc/api.py", line 89, in read
    path, repo=repo, rev=rev, remote=remote, mode=mode, encoding=encoding
  File "/home/sucess/anaconda3/lib/python3.7/contextlib.py", line 112, in __enter__
    return next(self.gen)
  File "/home/sucess/anaconda3/lib/python3.7/site-packages/dvc/api.py", line 77, in _open
    path, remote=remote, mode=mode, encoding=encoding
  File "/home/sucess/anaconda3/lib/python3.7/contextlib.py", line 112, in __enter__
    return next(self.gen)
  File "/home/sucess/anaconda3/lib/python3.7/site-packages/dvc/repo/__init__.py", line 503, in open_by_relpath
    raise FileMissingError(path) from exc
dvc.exceptions.FileMissingError: Can't find 'data/train_store.csv.dvc' neither locally nor on remote
2022-09-09 07:48:49,483 — FileHandler — INFO — DVC: CSV file read with path: data/test.csv | version: v5 | from: ../
2022-09-09 07:48:49,536 — FileHandler — INFO — DVC: CSV file read with path: data/store.csv | version: vs | from: ../
2022-09-09 07:49:17,047 — FileHandler — ERROR — DVC data getter raised an exception
Traceback (most recent call last):
  File "/home/sucess/anaconda3/lib/python3.7/site-packages/dvc/scm.py", line 140, in resolve_rev
    return scm.resolve_rev(fix_exp_head(scm, rev))
  File "/home/sucess/anaconda3/lib/python3.7/site-packages/scmrepo/git/__init__.py", line 289, in _backend_func
    result = func(*args, **kwargs)
  File "/home/sucess/anaconda3/lib/python3.7/site-packages/scmrepo/git/backend/pygit2.py", line 297, in resolve_rev
    raise RevError(f"unknown Git revision '{rev}'")
scmrepo.exceptions.RevError: unknown Git revision 'v_train_store'

During handling of the above exception, another exception occurred:

Traceback (most recent call last):
  File "../src/file_handler.py", line 25, in dvc_get_data
    rev=version)
  File "/home/sucess/anaconda3/lib/python3.7/site-packages/dvc/api.py", line 89, in read
    path, repo=repo, rev=rev, remote=remote, mode=mode, encoding=encoding
  File "/home/sucess/anaconda3/lib/python3.7/contextlib.py", line 112, in __enter__
    return next(self.gen)
  File "/home/sucess/anaconda3/lib/python3.7/site-packages/dvc/api.py", line 75, in _open
    with Repo.open(repo, rev=rev, subrepos=True, uninitialized=True) as _repo:
  File "/home/sucess/anaconda3/lib/python3.7/site-packages/dvc/repo/__init__.py", line 233, in open
    return Repo(url, *args, **kwargs)
  File "/home/sucess/anaconda3/lib/python3.7/site-packages/dvc/repo/__init__.py", line 176, in __init__
    root_dir=root_dir, fs=self.fs, uninitialized=uninitialized
  File "/home/sucess/anaconda3/lib/python3.7/site-packages/dvc/repo/__init__.py", line 95, in _get_repo_dirs
    root_dir = self.find_root(root_dir, fs)
  File "/home/sucess/anaconda3/lib/python3.7/site-packages/dvc/repo/__init__.py", line 319, in find_root
    if not fs.isdir(root_dir):
  File "/home/sucess/anaconda3/lib/python3.7/site-packages/dvc/fs/base.py", line 168, in isdir
    return self.fs.isdir(path)
  File "/home/sucess/anaconda3/lib/python3.7/site-packages/funcy/objects.py", line 50, in __get__
    return prop.__get__(instance, type)
  File "/home/sucess/anaconda3/lib/python3.7/site-packages/funcy/objects.py", line 28, in __get__
    res = instance.__dict__[self.fget.__name__] = self.fget(instance)
  File "/home/sucess/anaconda3/lib/python3.7/site-packages/dvc/fs/git.py", line 48, in fs
    return FsspecGitFileSystem(**self.fs_args)
  File "/home/sucess/anaconda3/lib/python3.7/site-packages/fsspec/spec.py", line 76, in __call__
    obj = super().__call__(*args, **kwargs)
  File "/home/sucess/anaconda3/lib/python3.7/site-packages/scmrepo/fs.py", line 54, in __init__
    resolved = resolver(scm, rev or "HEAD")
  File "/home/sucess/anaconda3/lib/python3.7/site-packages/dvc/scm.py", line 157, in resolve_rev
    raise RevError(str(exc))
dvc.scm.RevError: unknown Git revision 'v_train_store'
2022-09-09 07:49:17,751 — FileHandler — INFO — DVC: CSV file read with path: data/test.csv | version: v5 | from: ../
2022-09-09 07:49:17,778 — FileHandler — INFO — DVC: CSV file read with path: data/store.csv | version: vs | from: ../
2022-09-09 07:49:43,559 — FileHandler — ERROR — DVC data getter raised an exception
Traceback (most recent call last):
  File "/home/sucess/anaconda3/lib/python3.7/site-packages/dvc/scm.py", line 140, in resolve_rev
    return scm.resolve_rev(fix_exp_head(scm, rev))
  File "/home/sucess/anaconda3/lib/python3.7/site-packages/scmrepo/git/__init__.py", line 289, in _backend_func
    result = func(*args, **kwargs)
  File "/home/sucess/anaconda3/lib/python3.7/site-packages/scmrepo/git/backend/pygit2.py", line 297, in resolve_rev
    raise RevError(f"unknown Git revision '{rev}'")
scmrepo.exceptions.RevError: unknown Git revision 'v_train_store'

During handling of the above exception, another exception occurred:

Traceback (most recent call last):
  File "../src/file_handler.py", line 25, in dvc_get_data
    rev=version)
  File "/home/sucess/anaconda3/lib/python3.7/site-packages/dvc/api.py", line 89, in read
    path, repo=repo, rev=rev, remote=remote, mode=mode, encoding=encoding
  File "/home/sucess/anaconda3/lib/python3.7/contextlib.py", line 112, in __enter__
    return next(self.gen)
  File "/home/sucess/anaconda3/lib/python3.7/site-packages/dvc/api.py", line 75, in _open
    with Repo.open(repo, rev=rev, subrepos=True, uninitialized=True) as _repo:
  File "/home/sucess/anaconda3/lib/python3.7/site-packages/dvc/repo/__init__.py", line 233, in open
    return Repo(url, *args, **kwargs)
  File "/home/sucess/anaconda3/lib/python3.7/site-packages/dvc/repo/__init__.py", line 176, in __init__
    root_dir=root_dir, fs=self.fs, uninitialized=uninitialized
  File "/home/sucess/anaconda3/lib/python3.7/site-packages/dvc/repo/__init__.py", line 95, in _get_repo_dirs
    root_dir = self.find_root(root_dir, fs)
  File "/home/sucess/anaconda3/lib/python3.7/site-packages/dvc/repo/__init__.py", line 319, in find_root
    if not fs.isdir(root_dir):
  File "/home/sucess/anaconda3/lib/python3.7/site-packages/dvc/fs/base.py", line 168, in isdir
    return self.fs.isdir(path)
  File "/home/sucess/anaconda3/lib/python3.7/site-packages/funcy/objects.py", line 50, in __get__
    return prop.__get__(instance, type)
  File "/home/sucess/anaconda3/lib/python3.7/site-packages/funcy/objects.py", line 28, in __get__
    res = instance.__dict__[self.fget.__name__] = self.fget(instance)
  File "/home/sucess/anaconda3/lib/python3.7/site-packages/dvc/fs/git.py", line 48, in fs
    return FsspecGitFileSystem(**self.fs_args)
  File "/home/sucess/anaconda3/lib/python3.7/site-packages/fsspec/spec.py", line 76, in __call__
    obj = super().__call__(*args, **kwargs)
  File "/home/sucess/anaconda3/lib/python3.7/site-packages/scmrepo/fs.py", line 54, in __init__
    resolved = resolver(scm, rev or "HEAD")
  File "/home/sucess/anaconda3/lib/python3.7/site-packages/dvc/scm.py", line 157, in resolve_rev
    raise RevError(str(exc))
dvc.scm.RevError: unknown Git revision 'v_train_store'
2022-09-09 07:49:43,657 — FileHandler — INFO — DVC: CSV file read with path: data/test.csv | version: v5 | from: ../
2022-09-09 07:49:43,715 — FileHandler — INFO — DVC: CSV file read with path: data/store.csv | version: vs | from: ../
2022-09-09 07:50:33,284 — FileHandler — ERROR — DVC data getter raised an exception
Traceback (most recent call last):
  File "/home/sucess/anaconda3/lib/python3.7/site-packages/dvc/fs/dvc.py", line 114, in info
    outs = list(self.repo.index.tree.iteritems(key))
  File "/home/sucess/anaconda3/lib/python3.7/site-packages/dvc/data/tree.py", line 92, in iteritems
    for key, (meta, hash_info) in self._trie.iteritems(**kwargs):
  File "/home/sucess/anaconda3/lib/python3.7/site-packages/pygtrie.py", line 718, in iteritems
    node, _ = self._get_node(prefix)
  File "/home/sucess/anaconda3/lib/python3.7/site-packages/pygtrie.py", line 630, in _get_node
    raise KeyError(key)
KeyError: ('repo', 'data', 'train_store.csv')

The above exception was the direct cause of the following exception:

Traceback (most recent call last):
  File "/home/sucess/anaconda3/lib/python3.7/site-packages/dvc/repo/__init__.py", line 499, in open_by_relpath
    path, mode=mode, encoding=encoding, remote=remote
  File "/home/sucess/anaconda3/lib/python3.7/site-packages/dvc/fs/base.py", line 186, in open
    return self.fs.open(path, mode=mode, encoding=encoding, **kwargs)
  File "/home/sucess/anaconda3/lib/python3.7/site-packages/dvc/fs/repo.py", line 309, in open
    return dvc_fs.open(dvc_path, mode=mode, encoding=encoding, **kwargs)
  File "/home/sucess/anaconda3/lib/python3.7/site-packages/dvc/fs/base.py", line 186, in open
    return self.fs.open(path, mode=mode, encoding=encoding, **kwargs)
  File "/home/sucess/anaconda3/lib/python3.7/site-packages/dvc/fs/dvc.py", line 77, in open
    fs, fspath = self._get_fs_path(path, **kwargs)
  File "/home/sucess/anaconda3/lib/python3.7/site-packages/dvc/fs/dvc.py", line 54, in _get_fs_path
    info = self.info(path)
  File "/home/sucess/anaconda3/lib/python3.7/site-packages/dvc/fs/dvc.py", line 116, in info
    raise FileNotFoundError from exc
FileNotFoundError

The above exception was the direct cause of the following exception:

Traceback (most recent call last):
  File "../src/file_handler.py", line 25, in dvc_get_data
    rev=version)
  File "/home/sucess/anaconda3/lib/python3.7/site-packages/dvc/api.py", line 89, in read
    path, repo=repo, rev=rev, remote=remote, mode=mode, encoding=encoding
  File "/home/sucess/anaconda3/lib/python3.7/contextlib.py", line 112, in __enter__
    return next(self.gen)
  File "/home/sucess/anaconda3/lib/python3.7/site-packages/dvc/api.py", line 77, in _open
    path, remote=remote, mode=mode, encoding=encoding
  File "/home/sucess/anaconda3/lib/python3.7/contextlib.py", line 112, in __enter__
    return next(self.gen)
  File "/home/sucess/anaconda3/lib/python3.7/site-packages/dvc/repo/__init__.py", line 503, in open_by_relpath
    raise FileMissingError(path) from exc
dvc.exceptions.FileMissingError: Can't find 'data/train_store.csv' neither locally nor on remote
2022-09-09 07:50:33,358 — FileHandler — INFO — DVC: CSV file read with path: data/test.csv | version: v5 | from: ../
2022-09-09 07:50:33,393 — FileHandler — INFO — DVC: CSV file read with path: data/store.csv | version: vs | from: ../
2022-09-09 07:51:02,897 — FileHandler — INFO — DVC: CSV file read with path: data/train.csv | version: v3 | from: ../
2022-09-09 07:51:02,966 — FileHandler — INFO — DVC: CSV file read with path: data/test.csv | version: v5 | from: ../
2022-09-09 07:51:02,995 — FileHandler — INFO — DVC: CSV file read with path: data/store.csv | version: vs | from: ../
2022-09-09 07:56:24,909 — FileHandler — INFO — DVC: CSV file read with path: data/train_store.csv | version: vts1 | from: ../
2022-09-09 07:56:25,520 — FileHandler — ERROR — DVC data getter raised an exception
Traceback (most recent call last):
  File "/home/sucess/anaconda3/lib/python3.7/site-packages/dvc/fs/dvc.py", line 114, in info
    outs = list(self.repo.index.tree.iteritems(key))
  File "/home/sucess/anaconda3/lib/python3.7/site-packages/dvc/data/tree.py", line 92, in iteritems
    for key, (meta, hash_info) in self._trie.iteritems(**kwargs):
  File "/home/sucess/anaconda3/lib/python3.7/site-packages/pygtrie.py", line 718, in iteritems
    node, _ = self._get_node(prefix)
  File "/home/sucess/anaconda3/lib/python3.7/site-packages/pygtrie.py", line 630, in _get_node
    raise KeyError(key)
KeyError: ('repo', 'data', 'test_store.csv')

The above exception was the direct cause of the following exception:

Traceback (most recent call last):
  File "/home/sucess/anaconda3/lib/python3.7/site-packages/dvc/repo/__init__.py", line 499, in open_by_relpath
    path, mode=mode, encoding=encoding, remote=remote
  File "/home/sucess/anaconda3/lib/python3.7/site-packages/dvc/fs/base.py", line 186, in open
    return self.fs.open(path, mode=mode, encoding=encoding, **kwargs)
  File "/home/sucess/anaconda3/lib/python3.7/site-packages/dvc/fs/repo.py", line 309, in open
    return dvc_fs.open(dvc_path, mode=mode, encoding=encoding, **kwargs)
  File "/home/sucess/anaconda3/lib/python3.7/site-packages/dvc/fs/base.py", line 186, in open
    return self.fs.open(path, mode=mode, encoding=encoding, **kwargs)
  File "/home/sucess/anaconda3/lib/python3.7/site-packages/dvc/fs/dvc.py", line 77, in open
    fs, fspath = self._get_fs_path(path, **kwargs)
  File "/home/sucess/anaconda3/lib/python3.7/site-packages/dvc/fs/dvc.py", line 54, in _get_fs_path
    info = self.info(path)
  File "/home/sucess/anaconda3/lib/python3.7/site-packages/dvc/fs/dvc.py", line 116, in info
    raise FileNotFoundError from exc
FileNotFoundError

The above exception was the direct cause of the following exception:

Traceback (most recent call last):
  File "../src/file_handler.py", line 25, in dvc_get_data
    rev=version)
  File "/home/sucess/anaconda3/lib/python3.7/site-packages/dvc/api.py", line 89, in read
    path, repo=repo, rev=rev, remote=remote, mode=mode, encoding=encoding
  File "/home/sucess/anaconda3/lib/python3.7/contextlib.py", line 112, in __enter__
    return next(self.gen)
  File "/home/sucess/anaconda3/lib/python3.7/site-packages/dvc/api.py", line 77, in _open
    path, remote=remote, mode=mode, encoding=encoding
  File "/home/sucess/anaconda3/lib/python3.7/contextlib.py", line 112, in __enter__
    return next(self.gen)
  File "/home/sucess/anaconda3/lib/python3.7/site-packages/dvc/repo/__init__.py", line 503, in open_by_relpath
    raise FileMissingError(path) from exc
dvc.exceptions.FileMissingError: Can't find 'data/test_store.csv' neither locally nor on remote
2022-09-09 07:58:51,593 — FileHandler — INFO — DVC: CSV file read with path: data/train_store.csv | version: vts1 | from: ../
2022-09-09 07:58:51,752 — FileHandler — INFO — DVC: CSV file read with path: data/test_store.csv | version: vts2 | from: ../
2022-09-09 09:57:53,550 — FileHandler — INFO — DVC: CSV file read with path: data/train.csv | version: v3 | from: ../
2022-09-09 09:57:53,692 — FileHandler — INFO — DVC: CSV file read with path: data/test.csv | version: v5 | from: ../
2022-09-09 09:57:53,816 — FileHandler — INFO — DVC: CSV file read with path: data/store.csv | version: vs | from: ../
2022-09-09 09:58:25,810 — FileHandler — INFO — DVC: CSV file read with path: data/train_store.csv | version: vts1 | from: ../
2022-09-09 09:58:26,092 — FileHandler — INFO — DVC: CSV file read with path: data/test_store.csv | version: vts2 | from: ../
2022-09-09 10:27:25,015 — FileHandler — INFO — DVC: CSV file read with path: data/train.csv | version: v3 | from: ../
2022-09-09 10:27:25,113 — FileHandler — INFO — DVC: CSV file read with path: data/test.csv | version: v5 | from: ../
2022-09-09 10:27:25,172 — FileHandler — INFO — DVC: CSV file read with path: data/store.csv | version: vs | from: ../
2022-09-09 10:28:01,663 — FileHandler — INFO — DVC: CSV file read with path: data/train_store.csv | version: vts1 | from: ../
2022-09-09 10:28:05,116 — FileHandler — INFO — DVC: CSV file read with path: data/test_store.csv | version: vts2 | from: ../
2022-09-09 10:52:26,076 — FileHandler — INFO — DVC: CSV file read with path: data/train.csv | version: vts1 | from: ../
2022-09-09 10:52:27,717 — FileHandler — INFO — DVC: CSV file read with path: data/test.csv | version: vts2 | from: ../
2022-09-09 10:53:50,681 — FileHandler — INFO — DVC: CSV file read with path: data/train.csv | version: v3 | from: ../
2022-09-09 10:53:55,800 — FileHandler — INFO — DVC: CSV file read with path: data/test.csv | version: v5 | from: ../
2022-09-09 10:56:31,442 — FileHandler — INFO — DVC: CSV file read with path: data/train.csv | version: v3 | from: ../
2022-09-09 10:56:35,567 — FileHandler — INFO — DVC: CSV file read with path: data/test.csv | version: v5 | from: ../
2022-09-09 10:58:09,758 — FileHandler — INFO — DVC: CSV file read with path: data/train.csv | version: vts1 | from: ../
2022-09-09 10:58:16,453 — FileHandler — INFO — DVC: CSV file read with path: data/test.csv | version: vts2 | from: ../
2022-09-09 11:03:10,765 — FileHandler — INFO — DVC: CSV file read with path: data/train.csv | version: vts1 | from: ../
2022-09-09 11:03:10,862 — FileHandler — INFO — DVC: CSV file read with path: data/test.csv | version: vts2 | from: ../
2022-09-09 11:03:27,554 — FileHandler — INFO — DVC: CSV file read with path: data/train_store.csv | version: vts1 | from: ../
2022-09-09 11:03:34,310 — FileHandler — INFO — DVC: CSV file read with path: data/test_store.csv | version: vts2 | from: ../
2022-09-09 13:35:36,596 — FileHandler — ERROR — DVC data getter raised an exception
Traceback (most recent call last):
  File "/home/sucess/anaconda3/lib/python3.7/site-packages/dvc/fs/dvc.py", line 114, in info
    outs = list(self.repo.index.tree.iteritems(key))
  File "/home/sucess/anaconda3/lib/python3.7/site-packages/dvc/data/tree.py", line 92, in iteritems
    for key, (meta, hash_info) in self._trie.iteritems(**kwargs):
  File "/home/sucess/anaconda3/lib/python3.7/site-packages/pygtrie.py", line 718, in iteritems
    node, _ = self._get_node(prefix)
  File "/home/sucess/anaconda3/lib/python3.7/site-packages/pygtrie.py", line 630, in _get_node
    raise KeyError(key)
KeyError: ('repo', 'data', 'train_store_label.csv')

The above exception was the direct cause of the following exception:

Traceback (most recent call last):
  File "/home/sucess/anaconda3/lib/python3.7/site-packages/dvc/repo/__init__.py", line 499, in open_by_relpath
    path, mode=mode, encoding=encoding, remote=remote
  File "/home/sucess/anaconda3/lib/python3.7/site-packages/dvc/fs/base.py", line 186, in open
    return self.fs.open(path, mode=mode, encoding=encoding, **kwargs)
  File "/home/sucess/anaconda3/lib/python3.7/site-packages/dvc/fs/repo.py", line 309, in open
    return dvc_fs.open(dvc_path, mode=mode, encoding=encoding, **kwargs)
  File "/home/sucess/anaconda3/lib/python3.7/site-packages/dvc/fs/base.py", line 186, in open
    return self.fs.open(path, mode=mode, encoding=encoding, **kwargs)
  File "/home/sucess/anaconda3/lib/python3.7/site-packages/dvc/fs/dvc.py", line 77, in open
    fs, fspath = self._get_fs_path(path, **kwargs)
  File "/home/sucess/anaconda3/lib/python3.7/site-packages/dvc/fs/dvc.py", line 54, in _get_fs_path
    info = self.info(path)
  File "/home/sucess/anaconda3/lib/python3.7/site-packages/dvc/fs/dvc.py", line 116, in info
    raise FileNotFoundError from exc
FileNotFoundError

The above exception was the direct cause of the following exception:

Traceback (most recent call last):
  File "../src/file_handler.py", line 25, in dvc_get_data
    rev=version)
  File "/home/sucess/anaconda3/lib/python3.7/site-packages/dvc/api.py", line 89, in read
    path, repo=repo, rev=rev, remote=remote, mode=mode, encoding=encoding
  File "/home/sucess/anaconda3/lib/python3.7/contextlib.py", line 112, in __enter__
    return next(self.gen)
  File "/home/sucess/anaconda3/lib/python3.7/site-packages/dvc/api.py", line 77, in _open
    path, remote=remote, mode=mode, encoding=encoding
  File "/home/sucess/anaconda3/lib/python3.7/contextlib.py", line 112, in __enter__
    return next(self.gen)
  File "/home/sucess/anaconda3/lib/python3.7/site-packages/dvc/repo/__init__.py", line 503, in open_by_relpath
    raise FileMissingError(path) from exc
dvc.exceptions.FileMissingError: Can't find 'data/train_store_label.csv' neither locally nor on remote
2022-09-09 13:36:28,401 — FileHandler — ERROR — DVC data getter raised an exception
Traceback (most recent call last):
  File "/home/sucess/anaconda3/lib/python3.7/site-packages/dvc/fs/dvc.py", line 114, in info
    outs = list(self.repo.index.tree.iteritems(key))
  File "/home/sucess/anaconda3/lib/python3.7/site-packages/dvc/data/tree.py", line 92, in iteritems
    for key, (meta, hash_info) in self._trie.iteritems(**kwargs):
  File "/home/sucess/anaconda3/lib/python3.7/site-packages/pygtrie.py", line 718, in iteritems
    node, _ = self._get_node(prefix)
  File "/home/sucess/anaconda3/lib/python3.7/site-packages/pygtrie.py", line 630, in _get_node
    raise KeyError(key)
KeyError: ('repo', 'data', 'train_store_label.csv')

The above exception was the direct cause of the following exception:

Traceback (most recent call last):
  File "/home/sucess/anaconda3/lib/python3.7/site-packages/dvc/repo/__init__.py", line 499, in open_by_relpath
    path, mode=mode, encoding=encoding, remote=remote
  File "/home/sucess/anaconda3/lib/python3.7/site-packages/dvc/fs/base.py", line 186, in open
    return self.fs.open(path, mode=mode, encoding=encoding, **kwargs)
  File "/home/sucess/anaconda3/lib/python3.7/site-packages/dvc/fs/repo.py", line 309, in open
    return dvc_fs.open(dvc_path, mode=mode, encoding=encoding, **kwargs)
  File "/home/sucess/anaconda3/lib/python3.7/site-packages/dvc/fs/base.py", line 186, in open
    return self.fs.open(path, mode=mode, encoding=encoding, **kwargs)
  File "/home/sucess/anaconda3/lib/python3.7/site-packages/dvc/fs/dvc.py", line 77, in open
    fs, fspath = self._get_fs_path(path, **kwargs)
  File "/home/sucess/anaconda3/lib/python3.7/site-packages/dvc/fs/dvc.py", line 54, in _get_fs_path
    info = self.info(path)
  File "/home/sucess/anaconda3/lib/python3.7/site-packages/dvc/fs/dvc.py", line 116, in info
    raise FileNotFoundError from exc
FileNotFoundError

The above exception was the direct cause of the following exception:

Traceback (most recent call last):
  File "../src/file_handler.py", line 25, in dvc_get_data
    rev=version)
  File "/home/sucess/anaconda3/lib/python3.7/site-packages/dvc/api.py", line 89, in read
    path, repo=repo, rev=rev, remote=remote, mode=mode, encoding=encoding
  File "/home/sucess/anaconda3/lib/python3.7/contextlib.py", line 112, in __enter__
    return next(self.gen)
  File "/home/sucess/anaconda3/lib/python3.7/site-packages/dvc/api.py", line 77, in _open
    path, remote=remote, mode=mode, encoding=encoding
  File "/home/sucess/anaconda3/lib/python3.7/contextlib.py", line 112, in __enter__
    return next(self.gen)
  File "/home/sucess/anaconda3/lib/python3.7/site-packages/dvc/repo/__init__.py", line 503, in open_by_relpath
    raise FileMissingError(path) from exc
dvc.exceptions.FileMissingError: Can't find 'data/train_store_label.csv' neither locally nor on remote
2022-09-09 22:12:12,686 — FileHandler — ERROR — DVC data getter raised an exception
Traceback (most recent call last):
  File "/home/sucess/anaconda3/lib/python3.7/site-packages/dvc/fs/dvc.py", line 114, in info
    outs = list(self.repo.index.tree.iteritems(key))
  File "/home/sucess/anaconda3/lib/python3.7/site-packages/dvc/data/tree.py", line 92, in iteritems
    for key, (meta, hash_info) in self._trie.iteritems(**kwargs):
  File "/home/sucess/anaconda3/lib/python3.7/site-packages/pygtrie.py", line 718, in iteritems
    node, _ = self._get_node(prefix)
  File "/home/sucess/anaconda3/lib/python3.7/site-packages/pygtrie.py", line 630, in _get_node
    raise KeyError(key)
KeyError: ('repo', 'data', 'train_store_label.csv')

The above exception was the direct cause of the following exception:

Traceback (most recent call last):
  File "/home/sucess/anaconda3/lib/python3.7/site-packages/dvc/repo/__init__.py", line 499, in open_by_relpath
    path, mode=mode, encoding=encoding, remote=remote
  File "/home/sucess/anaconda3/lib/python3.7/site-packages/dvc/fs/base.py", line 186, in open
    return self.fs.open(path, mode=mode, encoding=encoding, **kwargs)
  File "/home/sucess/anaconda3/lib/python3.7/site-packages/dvc/fs/repo.py", line 309, in open
    return dvc_fs.open(dvc_path, mode=mode, encoding=encoding, **kwargs)
  File "/home/sucess/anaconda3/lib/python3.7/site-packages/dvc/fs/base.py", line 186, in open
    return self.fs.open(path, mode=mode, encoding=encoding, **kwargs)
  File "/home/sucess/anaconda3/lib/python3.7/site-packages/dvc/fs/dvc.py", line 77, in open
    fs, fspath = self._get_fs_path(path, **kwargs)
  File "/home/sucess/anaconda3/lib/python3.7/site-packages/dvc/fs/dvc.py", line 54, in _get_fs_path
    info = self.info(path)
  File "/home/sucess/anaconda3/lib/python3.7/site-packages/dvc/fs/dvc.py", line 116, in info
    raise FileNotFoundError from exc
FileNotFoundError

The above exception was the direct cause of the following exception:

Traceback (most recent call last):
  File "../src/file_handler.py", line 25, in dvc_get_data
    rev=version)
  File "/home/sucess/anaconda3/lib/python3.7/site-packages/dvc/api.py", line 89, in read
    path, repo=repo, rev=rev, remote=remote, mode=mode, encoding=encoding
  File "/home/sucess/anaconda3/lib/python3.7/contextlib.py", line 112, in __enter__
    return next(self.gen)
  File "/home/sucess/anaconda3/lib/python3.7/site-packages/dvc/api.py", line 77, in _open
    path, remote=remote, mode=mode, encoding=encoding
  File "/home/sucess/anaconda3/lib/python3.7/contextlib.py", line 112, in __enter__
    return next(self.gen)
  File "/home/sucess/anaconda3/lib/python3.7/site-packages/dvc/repo/__init__.py", line 503, in open_by_relpath
    raise FileMissingError(path) from exc
dvc.exceptions.FileMissingError: Can't find 'data/train_store_label.csv' neither locally nor on remote
2022-09-09 22:16:48,610 — FileHandler — ERROR — DVC data getter raised an exception
Traceback (most recent call last):
  File "/home/sucess/anaconda3/lib/python3.7/site-packages/dvc/fs/dvc.py", line 114, in info
    outs = list(self.repo.index.tree.iteritems(key))
  File "/home/sucess/anaconda3/lib/python3.7/site-packages/dvc/data/tree.py", line 92, in iteritems
    for key, (meta, hash_info) in self._trie.iteritems(**kwargs):
  File "/home/sucess/anaconda3/lib/python3.7/site-packages/pygtrie.py", line 718, in iteritems
    node, _ = self._get_node(prefix)
  File "/home/sucess/anaconda3/lib/python3.7/site-packages/pygtrie.py", line 630, in _get_node
    raise KeyError(key)
KeyError: ('repo', 'data', 'train_store_label.csv')

The above exception was the direct cause of the following exception:

Traceback (most recent call last):
  File "/home/sucess/anaconda3/lib/python3.7/site-packages/dvc/repo/__init__.py", line 499, in open_by_relpath
    path, mode=mode, encoding=encoding, remote=remote
  File "/home/sucess/anaconda3/lib/python3.7/site-packages/dvc/fs/base.py", line 186, in open
    return self.fs.open(path, mode=mode, encoding=encoding, **kwargs)
  File "/home/sucess/anaconda3/lib/python3.7/site-packages/dvc/fs/repo.py", line 309, in open
    return dvc_fs.open(dvc_path, mode=mode, encoding=encoding, **kwargs)
  File "/home/sucess/anaconda3/lib/python3.7/site-packages/dvc/fs/base.py", line 186, in open
    return self.fs.open(path, mode=mode, encoding=encoding, **kwargs)
  File "/home/sucess/anaconda3/lib/python3.7/site-packages/dvc/fs/dvc.py", line 77, in open
    fs, fspath = self._get_fs_path(path, **kwargs)
  File "/home/sucess/anaconda3/lib/python3.7/site-packages/dvc/fs/dvc.py", line 54, in _get_fs_path
    info = self.info(path)
  File "/home/sucess/anaconda3/lib/python3.7/site-packages/dvc/fs/dvc.py", line 116, in info
    raise FileNotFoundError from exc
FileNotFoundError

The above exception was the direct cause of the following exception:

Traceback (most recent call last):
  File "../src/file_handler.py", line 25, in dvc_get_data
    rev=version)
  File "/home/sucess/anaconda3/lib/python3.7/site-packages/dvc/api.py", line 89, in read
    path, repo=repo, rev=rev, remote=remote, mode=mode, encoding=encoding
  File "/home/sucess/anaconda3/lib/python3.7/contextlib.py", line 112, in __enter__
    return next(self.gen)
  File "/home/sucess/anaconda3/lib/python3.7/site-packages/dvc/api.py", line 77, in _open
    path, remote=remote, mode=mode, encoding=encoding
  File "/home/sucess/anaconda3/lib/python3.7/contextlib.py", line 112, in __enter__
    return next(self.gen)
  File "/home/sucess/anaconda3/lib/python3.7/site-packages/dvc/repo/__init__.py", line 503, in open_by_relpath
    raise FileMissingError(path) from exc
dvc.exceptions.FileMissingError: Can't find 'data/train_store_label.csv' neither locally nor on remote
2022-09-09 22:17:25,558 — FileHandler — ERROR — DVC data getter raised an exception
Traceback (most recent call last):
  File "/home/sucess/anaconda3/lib/python3.7/site-packages/dvc/fs/dvc.py", line 114, in info
    outs = list(self.repo.index.tree.iteritems(key))
  File "/home/sucess/anaconda3/lib/python3.7/site-packages/dvc/data/tree.py", line 92, in iteritems
    for key, (meta, hash_info) in self._trie.iteritems(**kwargs):
  File "/home/sucess/anaconda3/lib/python3.7/site-packages/pygtrie.py", line 718, in iteritems
    node, _ = self._get_node(prefix)
  File "/home/sucess/anaconda3/lib/python3.7/site-packages/pygtrie.py", line 630, in _get_node
    raise KeyError(key)
KeyError: ('repo', 'data', 'train_store_label.csv')

The above exception was the direct cause of the following exception:

Traceback (most recent call last):
  File "/home/sucess/anaconda3/lib/python3.7/site-packages/dvc/repo/__init__.py", line 499, in open_by_relpath
    path, mode=mode, encoding=encoding, remote=remote
  File "/home/sucess/anaconda3/lib/python3.7/site-packages/dvc/fs/base.py", line 186, in open
    return self.fs.open(path, mode=mode, encoding=encoding, **kwargs)
  File "/home/sucess/anaconda3/lib/python3.7/site-packages/dvc/fs/repo.py", line 309, in open
    return dvc_fs.open(dvc_path, mode=mode, encoding=encoding, **kwargs)
  File "/home/sucess/anaconda3/lib/python3.7/site-packages/dvc/fs/base.py", line 186, in open
    return self.fs.open(path, mode=mode, encoding=encoding, **kwargs)
  File "/home/sucess/anaconda3/lib/python3.7/site-packages/dvc/fs/dvc.py", line 77, in open
    fs, fspath = self._get_fs_path(path, **kwargs)
  File "/home/sucess/anaconda3/lib/python3.7/site-packages/dvc/fs/dvc.py", line 54, in _get_fs_path
    info = self.info(path)
  File "/home/sucess/anaconda3/lib/python3.7/site-packages/dvc/fs/dvc.py", line 116, in info
    raise FileNotFoundError from exc
FileNotFoundError

The above exception was the direct cause of the following exception:

Traceback (most recent call last):
  File "../src/file_handler.py", line 25, in dvc_get_data
    rev=version)
  File "/home/sucess/anaconda3/lib/python3.7/site-packages/dvc/api.py", line 89, in read
    path, repo=repo, rev=rev, remote=remote, mode=mode, encoding=encoding
  File "/home/sucess/anaconda3/lib/python3.7/contextlib.py", line 112, in __enter__
    return next(self.gen)
  File "/home/sucess/anaconda3/lib/python3.7/site-packages/dvc/api.py", line 77, in _open
    path, remote=remote, mode=mode, encoding=encoding
  File "/home/sucess/anaconda3/lib/python3.7/contextlib.py", line 112, in __enter__
    return next(self.gen)
  File "/home/sucess/anaconda3/lib/python3.7/site-packages/dvc/repo/__init__.py", line 503, in open_by_relpath
    raise FileMissingError(path) from exc
dvc.exceptions.FileMissingError: Can't find 'data/train_store_label.csv' neither locally nor on remote
2022-09-09 22:18:08,693 — FileHandler — ERROR — DVC data getter raised an exception
Traceback (most recent call last):
  File "/home/sucess/anaconda3/lib/python3.7/site-packages/dvc/scm.py", line 140, in resolve_rev
    return scm.resolve_rev(fix_exp_head(scm, rev))
  File "/home/sucess/anaconda3/lib/python3.7/site-packages/scmrepo/git/__init__.py", line 289, in _backend_func
    result = func(*args, **kwargs)
  File "/home/sucess/anaconda3/lib/python3.7/site-packages/scmrepo/git/backend/pygit2.py", line 297, in resolve_rev
    raise RevError(f"unknown Git revision '{rev}'")
scmrepo.exceptions.RevError: unknown Git revision 'vsl'

During handling of the above exception, another exception occurred:

Traceback (most recent call last):
  File "../src/file_handler.py", line 25, in dvc_get_data
    rev=version)
  File "/home/sucess/anaconda3/lib/python3.7/site-packages/dvc/api.py", line 89, in read
    path, repo=repo, rev=rev, remote=remote, mode=mode, encoding=encoding
  File "/home/sucess/anaconda3/lib/python3.7/contextlib.py", line 112, in __enter__
    return next(self.gen)
  File "/home/sucess/anaconda3/lib/python3.7/site-packages/dvc/api.py", line 75, in _open
    with Repo.open(repo, rev=rev, subrepos=True, uninitialized=True) as _repo:
  File "/home/sucess/anaconda3/lib/python3.7/site-packages/dvc/repo/__init__.py", line 233, in open
    return Repo(url, *args, **kwargs)
  File "/home/sucess/anaconda3/lib/python3.7/site-packages/dvc/repo/__init__.py", line 176, in __init__
    root_dir=root_dir, fs=self.fs, uninitialized=uninitialized
  File "/home/sucess/anaconda3/lib/python3.7/site-packages/dvc/repo/__init__.py", line 95, in _get_repo_dirs
    root_dir = self.find_root(root_dir, fs)
  File "/home/sucess/anaconda3/lib/python3.7/site-packages/dvc/repo/__init__.py", line 319, in find_root
    if not fs.isdir(root_dir):
  File "/home/sucess/anaconda3/lib/python3.7/site-packages/dvc/fs/base.py", line 168, in isdir
    return self.fs.isdir(path)
  File "/home/sucess/anaconda3/lib/python3.7/site-packages/funcy/objects.py", line 50, in __get__
    return prop.__get__(instance, type)
  File "/home/sucess/anaconda3/lib/python3.7/site-packages/funcy/objects.py", line 28, in __get__
    res = instance.__dict__[self.fget.__name__] = self.fget(instance)
  File "/home/sucess/anaconda3/lib/python3.7/site-packages/dvc/fs/git.py", line 48, in fs
    return FsspecGitFileSystem(**self.fs_args)
  File "/home/sucess/anaconda3/lib/python3.7/site-packages/fsspec/spec.py", line 76, in __call__
    obj = super().__call__(*args, **kwargs)
  File "/home/sucess/anaconda3/lib/python3.7/site-packages/scmrepo/fs.py", line 54, in __init__
    resolved = resolver(scm, rev or "HEAD")
  File "/home/sucess/anaconda3/lib/python3.7/site-packages/dvc/scm.py", line 157, in resolve_rev
    raise RevError(str(exc))
dvc.scm.RevError: unknown Git revision 'vsl'
2022-09-09 22:18:17,361 — FileHandler — ERROR — DVC data getter raised an exception
Traceback (most recent call last):
  File "/home/sucess/anaconda3/lib/python3.7/site-packages/dvc/fs/dvc.py", line 114, in info
    outs = list(self.repo.index.tree.iteritems(key))
  File "/home/sucess/anaconda3/lib/python3.7/site-packages/dvc/data/tree.py", line 92, in iteritems
    for key, (meta, hash_info) in self._trie.iteritems(**kwargs):
  File "/home/sucess/anaconda3/lib/python3.7/site-packages/pygtrie.py", line 718, in iteritems
    node, _ = self._get_node(prefix)
  File "/home/sucess/anaconda3/lib/python3.7/site-packages/pygtrie.py", line 630, in _get_node
    raise KeyError(key)
KeyError: ('repo', 'data', 'train_store_label.csv')

The above exception was the direct cause of the following exception:

Traceback (most recent call last):
  File "/home/sucess/anaconda3/lib/python3.7/site-packages/dvc/repo/__init__.py", line 499, in open_by_relpath
    path, mode=mode, encoding=encoding, remote=remote
  File "/home/sucess/anaconda3/lib/python3.7/site-packages/dvc/fs/base.py", line 186, in open
    return self.fs.open(path, mode=mode, encoding=encoding, **kwargs)
  File "/home/sucess/anaconda3/lib/python3.7/site-packages/dvc/fs/repo.py", line 309, in open
    return dvc_fs.open(dvc_path, mode=mode, encoding=encoding, **kwargs)
  File "/home/sucess/anaconda3/lib/python3.7/site-packages/dvc/fs/base.py", line 186, in open
    return self.fs.open(path, mode=mode, encoding=encoding, **kwargs)
  File "/home/sucess/anaconda3/lib/python3.7/site-packages/dvc/fs/dvc.py", line 77, in open
    fs, fspath = self._get_fs_path(path, **kwargs)
  File "/home/sucess/anaconda3/lib/python3.7/site-packages/dvc/fs/dvc.py", line 54, in _get_fs_path
    info = self.info(path)
  File "/home/sucess/anaconda3/lib/python3.7/site-packages/dvc/fs/dvc.py", line 116, in info
    raise FileNotFoundError from exc
FileNotFoundError

The above exception was the direct cause of the following exception:

Traceback (most recent call last):
  File "../src/file_handler.py", line 25, in dvc_get_data
    rev=version)
  File "/home/sucess/anaconda3/lib/python3.7/site-packages/dvc/api.py", line 89, in read
    path, repo=repo, rev=rev, remote=remote, mode=mode, encoding=encoding
  File "/home/sucess/anaconda3/lib/python3.7/contextlib.py", line 112, in __enter__
    return next(self.gen)
  File "/home/sucess/anaconda3/lib/python3.7/site-packages/dvc/api.py", line 77, in _open
    path, remote=remote, mode=mode, encoding=encoding
  File "/home/sucess/anaconda3/lib/python3.7/contextlib.py", line 112, in __enter__
    return next(self.gen)
  File "/home/sucess/anaconda3/lib/python3.7/site-packages/dvc/repo/__init__.py", line 503, in open_by_relpath
    raise FileMissingError(path) from exc
dvc.exceptions.FileMissingError: Can't find 'data/train_store_label.csv' neither locally nor on remote
2022-09-09 22:18:40,066 — FileHandler — ERROR — DVC data getter raised an exception
Traceback (most recent call last):
  File "/home/sucess/anaconda3/lib/python3.7/site-packages/dvc/fs/dvc.py", line 114, in info
    outs = list(self.repo.index.tree.iteritems(key))
  File "/home/sucess/anaconda3/lib/python3.7/site-packages/dvc/data/tree.py", line 92, in iteritems
    for key, (meta, hash_info) in self._trie.iteritems(**kwargs):
  File "/home/sucess/anaconda3/lib/python3.7/site-packages/pygtrie.py", line 718, in iteritems
    node, _ = self._get_node(prefix)
  File "/home/sucess/anaconda3/lib/python3.7/site-packages/pygtrie.py", line 630, in _get_node
    raise KeyError(key)
KeyError: ('repo', 'data', 'train_store_label.csv')

The above exception was the direct cause of the following exception:

Traceback (most recent call last):
  File "/home/sucess/anaconda3/lib/python3.7/site-packages/dvc/repo/__init__.py", line 499, in open_by_relpath
    path, mode=mode, encoding=encoding, remote=remote
  File "/home/sucess/anaconda3/lib/python3.7/site-packages/dvc/fs/base.py", line 186, in open
    return self.fs.open(path, mode=mode, encoding=encoding, **kwargs)
  File "/home/sucess/anaconda3/lib/python3.7/site-packages/dvc/fs/repo.py", line 309, in open
    return dvc_fs.open(dvc_path, mode=mode, encoding=encoding, **kwargs)
  File "/home/sucess/anaconda3/lib/python3.7/site-packages/dvc/fs/base.py", line 186, in open
    return self.fs.open(path, mode=mode, encoding=encoding, **kwargs)
  File "/home/sucess/anaconda3/lib/python3.7/site-packages/dvc/fs/dvc.py", line 77, in open
    fs, fspath = self._get_fs_path(path, **kwargs)
  File "/home/sucess/anaconda3/lib/python3.7/site-packages/dvc/fs/dvc.py", line 54, in _get_fs_path
    info = self.info(path)
  File "/home/sucess/anaconda3/lib/python3.7/site-packages/dvc/fs/dvc.py", line 116, in info
    raise FileNotFoundError from exc
FileNotFoundError

The above exception was the direct cause of the following exception:

Traceback (most recent call last):
  File "../src/file_handler.py", line 25, in dvc_get_data
    rev=version)
  File "/home/sucess/anaconda3/lib/python3.7/site-packages/dvc/api.py", line 89, in read
    path, repo=repo, rev=rev, remote=remote, mode=mode, encoding=encoding
  File "/home/sucess/anaconda3/lib/python3.7/contextlib.py", line 112, in __enter__
    return next(self.gen)
  File "/home/sucess/anaconda3/lib/python3.7/site-packages/dvc/api.py", line 77, in _open
    path, remote=remote, mode=mode, encoding=encoding
  File "/home/sucess/anaconda3/lib/python3.7/contextlib.py", line 112, in __enter__
    return next(self.gen)
  File "/home/sucess/anaconda3/lib/python3.7/site-packages/dvc/repo/__init__.py", line 503, in open_by_relpath
    raise FileMissingError(path) from exc
dvc.exceptions.FileMissingError: Can't find 'data/train_store_label.csv' neither locally nor on remote
2022-09-09 22:20:14,342 — FileHandler — ERROR — DVC data getter raised an exception
Traceback (most recent call last):
  File "/home/sucess/anaconda3/lib/python3.7/site-packages/dvc/fs/dvc.py", line 114, in info
    outs = list(self.repo.index.tree.iteritems(key))
  File "/home/sucess/anaconda3/lib/python3.7/site-packages/dvc/data/tree.py", line 92, in iteritems
    for key, (meta, hash_info) in self._trie.iteritems(**kwargs):
  File "/home/sucess/anaconda3/lib/python3.7/site-packages/pygtrie.py", line 718, in iteritems
    node, _ = self._get_node(prefix)
  File "/home/sucess/anaconda3/lib/python3.7/site-packages/pygtrie.py", line 630, in _get_node
    raise KeyError(key)
KeyError: ('repo', '..', 'data', 'train_store_label.csv')

The above exception was the direct cause of the following exception:

Traceback (most recent call last):
  File "/home/sucess/anaconda3/lib/python3.7/site-packages/dvc/repo/__init__.py", line 499, in open_by_relpath
    path, mode=mode, encoding=encoding, remote=remote
  File "/home/sucess/anaconda3/lib/python3.7/site-packages/dvc/fs/base.py", line 186, in open
    return self.fs.open(path, mode=mode, encoding=encoding, **kwargs)
  File "/home/sucess/anaconda3/lib/python3.7/site-packages/dvc/fs/repo.py", line 309, in open
    return dvc_fs.open(dvc_path, mode=mode, encoding=encoding, **kwargs)
  File "/home/sucess/anaconda3/lib/python3.7/site-packages/dvc/fs/base.py", line 186, in open
    return self.fs.open(path, mode=mode, encoding=encoding, **kwargs)
  File "/home/sucess/anaconda3/lib/python3.7/site-packages/dvc/fs/dvc.py", line 77, in open
    fs, fspath = self._get_fs_path(path, **kwargs)
  File "/home/sucess/anaconda3/lib/python3.7/site-packages/dvc/fs/dvc.py", line 54, in _get_fs_path
    info = self.info(path)
  File "/home/sucess/anaconda3/lib/python3.7/site-packages/dvc/fs/dvc.py", line 116, in info
    raise FileNotFoundError from exc
FileNotFoundError

The above exception was the direct cause of the following exception:

Traceback (most recent call last):
  File "../src/file_handler.py", line 25, in dvc_get_data
    rev=version)
  File "/home/sucess/anaconda3/lib/python3.7/site-packages/dvc/api.py", line 89, in read
    path, repo=repo, rev=rev, remote=remote, mode=mode, encoding=encoding
  File "/home/sucess/anaconda3/lib/python3.7/contextlib.py", line 112, in __enter__
    return next(self.gen)
  File "/home/sucess/anaconda3/lib/python3.7/site-packages/dvc/api.py", line 77, in _open
    path, remote=remote, mode=mode, encoding=encoding
  File "/home/sucess/anaconda3/lib/python3.7/contextlib.py", line 112, in __enter__
    return next(self.gen)
  File "/home/sucess/anaconda3/lib/python3.7/site-packages/dvc/repo/__init__.py", line 503, in open_by_relpath
    raise FileMissingError(path) from exc
dvc.exceptions.FileMissingError: Can't find '../data/train_store_label.csv' neither locally nor on remote
2022-09-09 22:20:30,432 — FileHandler — ERROR — DVC data getter raised an exception
Traceback (most recent call last):
  File "/home/sucess/anaconda3/lib/python3.7/site-packages/dvc/fs/dvc.py", line 114, in info
    outs = list(self.repo.index.tree.iteritems(key))
  File "/home/sucess/anaconda3/lib/python3.7/site-packages/dvc/data/tree.py", line 92, in iteritems
    for key, (meta, hash_info) in self._trie.iteritems(**kwargs):
  File "/home/sucess/anaconda3/lib/python3.7/site-packages/pygtrie.py", line 718, in iteritems
    node, _ = self._get_node(prefix)
  File "/home/sucess/anaconda3/lib/python3.7/site-packages/pygtrie.py", line 630, in _get_node
    raise KeyError(key)
KeyError: ('repo', '..', 'data', 'train_store_label.csv')

The above exception was the direct cause of the following exception:

Traceback (most recent call last):
  File "/home/sucess/anaconda3/lib/python3.7/site-packages/dvc/repo/__init__.py", line 499, in open_by_relpath
    path, mode=mode, encoding=encoding, remote=remote
  File "/home/sucess/anaconda3/lib/python3.7/site-packages/dvc/fs/base.py", line 186, in open
    return self.fs.open(path, mode=mode, encoding=encoding, **kwargs)
  File "/home/sucess/anaconda3/lib/python3.7/site-packages/dvc/fs/repo.py", line 309, in open
    return dvc_fs.open(dvc_path, mode=mode, encoding=encoding, **kwargs)
  File "/home/sucess/anaconda3/lib/python3.7/site-packages/dvc/fs/base.py", line 186, in open
    return self.fs.open(path, mode=mode, encoding=encoding, **kwargs)
  File "/home/sucess/anaconda3/lib/python3.7/site-packages/dvc/fs/dvc.py", line 77, in open
    fs, fspath = self._get_fs_path(path, **kwargs)
  File "/home/sucess/anaconda3/lib/python3.7/site-packages/dvc/fs/dvc.py", line 54, in _get_fs_path
    info = self.info(path)
  File "/home/sucess/anaconda3/lib/python3.7/site-packages/dvc/fs/dvc.py", line 116, in info
    raise FileNotFoundError from exc
FileNotFoundError

The above exception was the direct cause of the following exception:

Traceback (most recent call last):
  File "../src/file_handler.py", line 25, in dvc_get_data
    rev=version)
  File "/home/sucess/anaconda3/lib/python3.7/site-packages/dvc/api.py", line 89, in read
    path, repo=repo, rev=rev, remote=remote, mode=mode, encoding=encoding
  File "/home/sucess/anaconda3/lib/python3.7/contextlib.py", line 112, in __enter__
    return next(self.gen)
  File "/home/sucess/anaconda3/lib/python3.7/site-packages/dvc/api.py", line 77, in _open
    path, remote=remote, mode=mode, encoding=encoding
  File "/home/sucess/anaconda3/lib/python3.7/contextlib.py", line 112, in __enter__
    return next(self.gen)
  File "/home/sucess/anaconda3/lib/python3.7/site-packages/dvc/repo/__init__.py", line 503, in open_by_relpath
    raise FileMissingError(path) from exc
dvc.exceptions.FileMissingError: Can't find '../data/train_store_label.csv' neither locally nor on remote
2022-09-09 22:20:48,869 — FileHandler — ERROR — DVC data getter raised an exception
Traceback (most recent call last):
  File "/home/sucess/anaconda3/lib/python3.7/site-packages/dvc/fs/dvc.py", line 114, in info
    outs = list(self.repo.index.tree.iteritems(key))
  File "/home/sucess/anaconda3/lib/python3.7/site-packages/dvc/data/tree.py", line 92, in iteritems
    for key, (meta, hash_info) in self._trie.iteritems(**kwargs):
  File "/home/sucess/anaconda3/lib/python3.7/site-packages/pygtrie.py", line 718, in iteritems
    node, _ = self._get_node(prefix)
  File "/home/sucess/anaconda3/lib/python3.7/site-packages/pygtrie.py", line 630, in _get_node
    raise KeyError(key)
KeyError: ('repo', '..', 'data', 'train_store_label.csv')

The above exception was the direct cause of the following exception:

Traceback (most recent call last):
  File "/home/sucess/anaconda3/lib/python3.7/site-packages/dvc/repo/__init__.py", line 499, in open_by_relpath
    path, mode=mode, encoding=encoding, remote=remote
  File "/home/sucess/anaconda3/lib/python3.7/site-packages/dvc/fs/base.py", line 186, in open
    return self.fs.open(path, mode=mode, encoding=encoding, **kwargs)
  File "/home/sucess/anaconda3/lib/python3.7/site-packages/dvc/fs/repo.py", line 309, in open
    return dvc_fs.open(dvc_path, mode=mode, encoding=encoding, **kwargs)
  File "/home/sucess/anaconda3/lib/python3.7/site-packages/dvc/fs/base.py", line 186, in open
    return self.fs.open(path, mode=mode, encoding=encoding, **kwargs)
  File "/home/sucess/anaconda3/lib/python3.7/site-packages/dvc/fs/dvc.py", line 77, in open
    fs, fspath = self._get_fs_path(path, **kwargs)
  File "/home/sucess/anaconda3/lib/python3.7/site-packages/dvc/fs/dvc.py", line 54, in _get_fs_path
    info = self.info(path)
  File "/home/sucess/anaconda3/lib/python3.7/site-packages/dvc/fs/dvc.py", line 116, in info
    raise FileNotFoundError from exc
FileNotFoundError

The above exception was the direct cause of the following exception:

Traceback (most recent call last):
  File "../src/file_handler.py", line 25, in dvc_get_data
    rev=version)
  File "/home/sucess/anaconda3/lib/python3.7/site-packages/dvc/api.py", line 89, in read
    path, repo=repo, rev=rev, remote=remote, mode=mode, encoding=encoding
  File "/home/sucess/anaconda3/lib/python3.7/contextlib.py", line 112, in __enter__
    return next(self.gen)
  File "/home/sucess/anaconda3/lib/python3.7/site-packages/dvc/api.py", line 77, in _open
    path, remote=remote, mode=mode, encoding=encoding
  File "/home/sucess/anaconda3/lib/python3.7/contextlib.py", line 112, in __enter__
    return next(self.gen)
  File "/home/sucess/anaconda3/lib/python3.7/site-packages/dvc/repo/__init__.py", line 503, in open_by_relpath
    raise FileMissingError(path) from exc
dvc.exceptions.FileMissingError: Can't find '../data/train_store_label.csv' neither locally nor on remote
2022-09-09 22:20:55,398 — FileHandler — ERROR — DVC data getter raised an exception
Traceback (most recent call last):
  File "/home/sucess/anaconda3/lib/python3.7/site-packages/dvc/fs/dvc.py", line 114, in info
    outs = list(self.repo.index.tree.iteritems(key))
  File "/home/sucess/anaconda3/lib/python3.7/site-packages/dvc/data/tree.py", line 92, in iteritems
    for key, (meta, hash_info) in self._trie.iteritems(**kwargs):
  File "/home/sucess/anaconda3/lib/python3.7/site-packages/pygtrie.py", line 718, in iteritems
    node, _ = self._get_node(prefix)
  File "/home/sucess/anaconda3/lib/python3.7/site-packages/pygtrie.py", line 630, in _get_node
    raise KeyError(key)
KeyError: ('repo', '..', 'data', 'train_store_label.csv')

The above exception was the direct cause of the following exception:

Traceback (most recent call last):
  File "/home/sucess/anaconda3/lib/python3.7/site-packages/dvc/repo/__init__.py", line 499, in open_by_relpath
    path, mode=mode, encoding=encoding, remote=remote
  File "/home/sucess/anaconda3/lib/python3.7/site-packages/dvc/fs/base.py", line 186, in open
    return self.fs.open(path, mode=mode, encoding=encoding, **kwargs)
  File "/home/sucess/anaconda3/lib/python3.7/site-packages/dvc/fs/repo.py", line 309, in open
    return dvc_fs.open(dvc_path, mode=mode, encoding=encoding, **kwargs)
  File "/home/sucess/anaconda3/lib/python3.7/site-packages/dvc/fs/base.py", line 186, in open
    return self.fs.open(path, mode=mode, encoding=encoding, **kwargs)
  File "/home/sucess/anaconda3/lib/python3.7/site-packages/dvc/fs/dvc.py", line 77, in open
    fs, fspath = self._get_fs_path(path, **kwargs)
  File "/home/sucess/anaconda3/lib/python3.7/site-packages/dvc/fs/dvc.py", line 54, in _get_fs_path
    info = self.info(path)
  File "/home/sucess/anaconda3/lib/python3.7/site-packages/dvc/fs/dvc.py", line 116, in info
    raise FileNotFoundError from exc
FileNotFoundError

The above exception was the direct cause of the following exception:

Traceback (most recent call last):
  File "../src/file_handler.py", line 25, in dvc_get_data
    rev=version)
  File "/home/sucess/anaconda3/lib/python3.7/site-packages/dvc/api.py", line 89, in read
    path, repo=repo, rev=rev, remote=remote, mode=mode, encoding=encoding
  File "/home/sucess/anaconda3/lib/python3.7/contextlib.py", line 112, in __enter__
    return next(self.gen)
  File "/home/sucess/anaconda3/lib/python3.7/site-packages/dvc/api.py", line 77, in _open
    path, remote=remote, mode=mode, encoding=encoding
  File "/home/sucess/anaconda3/lib/python3.7/contextlib.py", line 112, in __enter__
    return next(self.gen)
  File "/home/sucess/anaconda3/lib/python3.7/site-packages/dvc/repo/__init__.py", line 503, in open_by_relpath
    raise FileMissingError(path) from exc
dvc.exceptions.FileMissingError: Can't find '../data/train_store_label.csv' neither locally nor on remote
2022-09-09 22:21:26,362 — FileHandler — ERROR — DVC data getter raised an exception
Traceback (most recent call last):
  File "/home/sucess/anaconda3/lib/python3.7/site-packages/dvc/fs/dvc.py", line 114, in info
    outs = list(self.repo.index.tree.iteritems(key))
  File "/home/sucess/anaconda3/lib/python3.7/site-packages/dvc/data/tree.py", line 92, in iteritems
    for key, (meta, hash_info) in self._trie.iteritems(**kwargs):
  File "/home/sucess/anaconda3/lib/python3.7/site-packages/pygtrie.py", line 718, in iteritems
    node, _ = self._get_node(prefix)
  File "/home/sucess/anaconda3/lib/python3.7/site-packages/pygtrie.py", line 630, in _get_node
    raise KeyError(key)
KeyError: ('repo', '..', 'data', 'train_store_label.csv')

The above exception was the direct cause of the following exception:

Traceback (most recent call last):
  File "/home/sucess/anaconda3/lib/python3.7/site-packages/dvc/repo/__init__.py", line 499, in open_by_relpath
    path, mode=mode, encoding=encoding, remote=remote
  File "/home/sucess/anaconda3/lib/python3.7/site-packages/dvc/fs/base.py", line 186, in open
    return self.fs.open(path, mode=mode, encoding=encoding, **kwargs)
  File "/home/sucess/anaconda3/lib/python3.7/site-packages/dvc/fs/repo.py", line 309, in open
    return dvc_fs.open(dvc_path, mode=mode, encoding=encoding, **kwargs)
  File "/home/sucess/anaconda3/lib/python3.7/site-packages/dvc/fs/base.py", line 186, in open
    return self.fs.open(path, mode=mode, encoding=encoding, **kwargs)
  File "/home/sucess/anaconda3/lib/python3.7/site-packages/dvc/fs/dvc.py", line 77, in open
    fs, fspath = self._get_fs_path(path, **kwargs)
  File "/home/sucess/anaconda3/lib/python3.7/site-packages/dvc/fs/dvc.py", line 54, in _get_fs_path
    info = self.info(path)
  File "/home/sucess/anaconda3/lib/python3.7/site-packages/dvc/fs/dvc.py", line 116, in info
    raise FileNotFoundError from exc
FileNotFoundError

The above exception was the direct cause of the following exception:

Traceback (most recent call last):
  File "../src/file_handler.py", line 25, in dvc_get_data
    rev=version)
  File "/home/sucess/anaconda3/lib/python3.7/site-packages/dvc/api.py", line 89, in read
    path, repo=repo, rev=rev, remote=remote, mode=mode, encoding=encoding
  File "/home/sucess/anaconda3/lib/python3.7/contextlib.py", line 112, in __enter__
    return next(self.gen)
  File "/home/sucess/anaconda3/lib/python3.7/site-packages/dvc/api.py", line 77, in _open
    path, remote=remote, mode=mode, encoding=encoding
  File "/home/sucess/anaconda3/lib/python3.7/contextlib.py", line 112, in __enter__
    return next(self.gen)
  File "/home/sucess/anaconda3/lib/python3.7/site-packages/dvc/repo/__init__.py", line 503, in open_by_relpath
    raise FileMissingError(path) from exc
dvc.exceptions.FileMissingError: Can't find '../data/train_store_label.csv' neither locally nor on remote
2022-09-09 22:22:16,189 — FileHandler — ERROR — DVC data getter raised an exception
Traceback (most recent call last):
  File "/home/sucess/anaconda3/lib/python3.7/site-packages/dvc/fs/dvc.py", line 114, in info
    outs = list(self.repo.index.tree.iteritems(key))
  File "/home/sucess/anaconda3/lib/python3.7/site-packages/dvc/data/tree.py", line 92, in iteritems
    for key, (meta, hash_info) in self._trie.iteritems(**kwargs):
  File "/home/sucess/anaconda3/lib/python3.7/site-packages/pygtrie.py", line 718, in iteritems
    node, _ = self._get_node(prefix)
  File "/home/sucess/anaconda3/lib/python3.7/site-packages/pygtrie.py", line 630, in _get_node
    raise KeyError(key)
KeyError: ('repo', '..', 'data', 'train_store_label.csv')

The above exception was the direct cause of the following exception:

Traceback (most recent call last):
  File "/home/sucess/anaconda3/lib/python3.7/site-packages/dvc/repo/__init__.py", line 499, in open_by_relpath
    path, mode=mode, encoding=encoding, remote=remote
  File "/home/sucess/anaconda3/lib/python3.7/site-packages/dvc/fs/base.py", line 186, in open
    return self.fs.open(path, mode=mode, encoding=encoding, **kwargs)
  File "/home/sucess/anaconda3/lib/python3.7/site-packages/dvc/fs/repo.py", line 309, in open
    return dvc_fs.open(dvc_path, mode=mode, encoding=encoding, **kwargs)
  File "/home/sucess/anaconda3/lib/python3.7/site-packages/dvc/fs/base.py", line 186, in open
    return self.fs.open(path, mode=mode, encoding=encoding, **kwargs)
  File "/home/sucess/anaconda3/lib/python3.7/site-packages/dvc/fs/dvc.py", line 77, in open
    fs, fspath = self._get_fs_path(path, **kwargs)
  File "/home/sucess/anaconda3/lib/python3.7/site-packages/dvc/fs/dvc.py", line 54, in _get_fs_path
    info = self.info(path)
  File "/home/sucess/anaconda3/lib/python3.7/site-packages/dvc/fs/dvc.py", line 116, in info
    raise FileNotFoundError from exc
FileNotFoundError

The above exception was the direct cause of the following exception:

Traceback (most recent call last):
  File "../src/file_handler.py", line 25, in dvc_get_data
    rev=version)
  File "/home/sucess/anaconda3/lib/python3.7/site-packages/dvc/api.py", line 89, in read
    path, repo=repo, rev=rev, remote=remote, mode=mode, encoding=encoding
  File "/home/sucess/anaconda3/lib/python3.7/contextlib.py", line 112, in __enter__
    return next(self.gen)
  File "/home/sucess/anaconda3/lib/python3.7/site-packages/dvc/api.py", line 77, in _open
    path, remote=remote, mode=mode, encoding=encoding
  File "/home/sucess/anaconda3/lib/python3.7/contextlib.py", line 112, in __enter__
    return next(self.gen)
  File "/home/sucess/anaconda3/lib/python3.7/site-packages/dvc/repo/__init__.py", line 503, in open_by_relpath
    raise FileMissingError(path) from exc
dvc.exceptions.FileMissingError: Can't find '../data/train_store_label.csv' neither locally nor on remote
